Workbook
Name AmortYears: Assumptions!$C$26
Name AnalysisStart: Assumptions!$C$16
Name CAM_PSF: Assumptions!$C$59
Name Capex_PSF: Assumptions!$C$67
Name Downtime_New: Assumptions!$C$53
Name Downtime_Ren: Assumptions!$C$54
Name ExitCap: Assumptions!$C$34
Name ExpGrowth: Assumptions!$C$64
Name FreeRent_New: Assumptions!$C$51
Name FreeRent_Ren: Assumptions!$C$52
Name GenVac: Assumptions!$C$65
Name GP_Pct: Assumptions!$C$71
Name HoldYears: Assumptions!$C$17
Name Ins_PSF: Assumptions!$C$60
Name IntRate: Assumptions!$C$25
Name IOYears: Assumptions!$C$27
Name LC_New: Assumptions!$C$49
Name LC_Ren: Assumptions!$C$50
Name LeaseTermYrs: Assumptions!$C$56
Name LoanAmount: Assumptions!$C$29
Name LoanFeePct: Assumptions!$C$28
Name LP_Pct: Assumptions!$C$70
Name LTV_Pct: Assumptions!$C$24
Name MgmtFeePct: Assumptions!$C$63
Name MktRentGrowth: Assumptions!$D$42:$M$42
Name MktRentSchedule: Assumptions!$D$44:$M$44
Name MktRentY1: Assumptions!$C$38
Name PrefRate: Assumptions!$C$73
Name PromoteGP: Assumptions!$C$75
Name PromoteLP: Assumptions!$C$74
Name PurchasePrice: Assumptions!$C$18
Name RecoveryPct: Assumptions!$C$66
Name RET_PSF: Assumptions!$C$61
Name Retention_Ratio: Assumptions!$C$55
Name SellingCostsPct: Assumptions!$C$35
Name TI_New: Assumptions!$C$47
Name TI_Ren: Assumptions!$C$48
Name TotalAcqCost: Assumptions!$C$21
Name TotalSF: Assumptions!$C$10
Name UT_PSF: Assumptions!$C$62

Sheet Summary
B2: DEAL SUMMARY & RETURNS
B3: One-page dashboard pulling from all other tabs
B5: PROPERTY | E5: DEAL TERMS
B6: Property Name | C6: =Assumptions!C6 -> Space Park South (Example) | E6: Analysis Start | F6: =AnalysisStart -> 45292
B7: Address | C7: =Assumptions!C7 -> 201 Space Park S. Dr. | E7: Hold Period | F7: =HoldYears -> 10
B8: City, State, Zip | C8: =Assumptions!C8 -> Nashville, TN 37211 | E8: Purchase Price | F8: =PurchasePrice -> 120000000
B9: Submarket | C9: =Assumptions!C9 -> Interchange City / Southeast | E9: Purchase Price PSF | F9: =Assumptions!C19 -> 98.944591
B10: Total SF | C10: =TotalSF -> 1212800 | E10: Total Acquisition Cost | F10: =TotalAcqCost -> 121200000
B11: Year Built | C11: =Assumptions!C12 -> 1974 | E11: Loan Amount | F11: =LoanAmount -> 72000000
B12: WALT (Occupied) | C12: ='Rent Roll'!D63 -> 2.0737225 | E12: LTV | F12: =LTV_Pct -> 0.6
B13: Occupancy | C13: ='Rent Roll'!D64 -> 0.85405673 | E13: Total Equity | F13: =TotalAcqCost-LoanAmount+LoanAmount*LoanFeePct -> 49920000
B15: PROPERTY-LEVEL RETURNS
B17: Unlevered IRR | C17: =_xlfn.IFNA(IRR('Cash Flow'!C50:M50),"N/A") -> 0.12221195 | E17: Levered IRR | F17: =_xlfn.IFNA(IRR('Cash Flow'!C51:M51),"N/A") -> 0.17138026
B18: Unlevered Equity Multiple | C18: =SUM('Cash Flow'!D50:M50)/ABS('Cash Flow'!C50) -> 2.6169547 | E18: Levered Equity Multiple | F18: =SUM('Cash Flow'!D51:M51)/ABS('Cash Flow'!C51) -> 4.0122908
B20: LP / GP RETURNS (After Waterfall)
B22: LP IRR | C22: =Waterfall!C61 -> 0.16071221 | E22: GP IRR (All GP Capital) | F22: =Waterfall!C63 -> 0.2884418
B23: LP Equity Multiple | C23: =Waterfall!C62 -> 3.6593883 | E23: GP Equity Multiple | F23: =Waterfall!C64 -> 10.717439
B24: GP Promote $ Earned | C24: =Waterfall!C65 -> 22314732
B26: VALUATION METRICS
B28: Year 1 NOI | C28: ='Cash Flow'!D25 -> 7089647.2 | E28: Going-In Cap Rate | F28: ='Cash Flow'!D25/PurchasePrice -> 0.059080393
B29: Year 10 NOI | C29: ='Cash Flow'!M25 -> 13615676 | E29: Exit Cap Rate | F29: =ExitCap -> 0.065
B30: Terminal NOI (Y11) | C30: ='Cash Flow'!N25 -> 14024146 | E30: Gross Sale Price (Y10) | F30: ='Cash Flow'!M43 -> 2.1575609e+08
B31: NOI Growth Y1→Y10 | C31: ='Cash Flow'!M25/'Cash Flow'!D25-1 -> 0.92050118 | E31: Net Sale Proceeds | F31: ='Cash Flow'!M45 -> 2.1251975e+08
B33: ANNUAL CASH FLOW SNAPSHOT
B35: Year | C35: NOI | E35: Unlev. Op CF | F35: Levered CoC
B36: 1 | C36: ='Cash Flow'!D25 -> 7089647.2 | E36: ='Cash Flow'!D33 -> 4905422.2 | F36: ='Cash Flow'!D40/(TotalAcqCost-LoanAmount+LoanAmount*LoanFeePct) -> 0.0045156688
B37: 2 | C37: ='Cash Flow'!E25 -> 9051421.7 | E37: ='Cash Flow'!E33 -> 7787212.7 | F37: ='Cash Flow'!E40/(TotalAcqCost-LoanAmount+LoanAmount*LoanFeePct) -> 0.062243845
B38: 3 | C38: ='Cash Flow'!F25 -> 10139110 | E38: ='Cash Flow'!F33 -> 9504684.1 | F38: ='Cash Flow'!F40/(TotalAcqCost-LoanAmount+LoanAmount*LoanFeePct) -> 0.081001931
B39: 4 | C39: ='Cash Flow'!G25 -> 10600287 | E39: ='Cash Flow'!G33 -> 9538341.6 | F39: ='Cash Flow'!G40/(TotalAcqCost-LoanAmount+LoanAmount*LoanFeePct) -> 0.081676159
B40: 5 | C40: ='Cash Flow'!H25 -> 11182023 | E40: ='Cash Flow'!H33 -> 9989487.9 | F40: ='Cash Flow'!H40/(TotalAcqCost-LoanAmount+LoanAmount*LoanFeePct) -> 0.090713546
B41: 6 | C41: ='Cash Flow'!I25 -> 12324987 | E41: ='Cash Flow'!I33 -> 11973495 | F41: ='Cash Flow'!I40/(TotalAcqCost-LoanAmount+LoanAmount*LoanFeePct) -> 0.13045727
B42: 7 | C42: ='Cash Flow'!J25 -> 12638320 | E42: ='Cash Flow'!J33 -> 12203373 | F42: ='Cash Flow'!J40/(TotalAcqCost-LoanAmount+LoanAmount*LoanFeePct) -> 0.1350622
B43: 8 | C43: ='Cash Flow'!K25 -> 12991790 | E43: ='Cash Flow'!K33 -> 12618893 | F43: ='Cash Flow'!K40/(TotalAcqCost-LoanAmount+LoanAmount*LoanFeePct) -> 0.14338591
B44: 9 | C44: ='Cash Flow'!L25 -> 13298261 | E44: ='Cash Flow'!L33 -> 12914177 | F44: ='Cash Flow'!L40/(TotalAcqCost-LoanAmount+LoanAmount*LoanFeePct) -> 0.14930106
B45: 10 | C45: ='Cash Flow'!M25 -> 13615676 | E45: ='Cash Flow'!M33 -> 13220069 | F45: ='Cash Flow'!M40/(TotalAcqCost-LoanAmount+LoanAmount*LoanFeePct) -> 0.1554287

Sheet Assumptions
B2: INDUSTRIAL UNDERWRITING MODEL — DEAL ASSUMPTIONS
B3: Blue = user inputs | Black = formulas | Green = cross-sheet links | Yellow = key sensitivities
B5: PROPERTY INFORMATION
B6: Property Name | C6: Space Park South (Example)
B7: Address | C7: 201 Space Park S. Dr.
B8: City, State, Zip | C8: Nashville, TN 37211
B9: Submarket | C9: Interchange City / Southeast
B10: Total Rentable SF | C10: 1212800
B11: Number of Buildings | C11: 8
B12: Year Built | C12: 1974
B13: Land Area (Acres) | C13: 66.6
B15: ACQUISITION
B16: Analysis Start Date | C16: 45292
B17: Hold Period (Years) | C17: 10
B18: Purchase Price | C18: 120000000
B19: Purchase Price PSF | C19: =C18/C10 -> 98.944591
B20: Closing Costs (% of Price) | C20: 0.01
B21: Total Acquisition Cost | C21: =C18*(1+C20) -> 121200000
B23: DEBT TERMS
B24: LTV | C24: 0.6
B25: Interest Rate | C25: 0.065
B26: Amortization (Years) | C26: 30
B27: Interest-Only Period (Years) | C27: 2
B28: Loan Fee (% of Loan) | C28: 0.01
B29: Loan Amount | C29: =C18*C24 -> 72000000
B30: Annual Debt Service (IO) | C30: =C29*C25 -> 4680000
B31: Annual Debt Service (Amortizing) | C31: =-PMT(C25/12,C26*12,C29)*12 -> 5461067.7
B33: EXIT ASSUMPTIONS
B34: Exit Cap Rate | C34: 0.065
B35: Selling Costs (% of Sale Price) | C35: 0.015
B37: MARKET RENT SCHEDULE
B38: Market Rent at Analysis Start ($/SF, NNN, Year 1) | C38: 10
B40: YoY Market Rent Growth — applied at start of each year:
D41: Y1→Y2 | E41: Y2→Y3 | F41: Y3→Y4 | G41: Y4→Y5 | H41: Y5→Y6 | I41: Y6→Y7 | J41: Y7→Y8 | K41: Y8→Y9 | L41: Y9→Y10 | M41: Y10→Y11
D42: 0.06 | E42: 0.045 | F42: 0.045 | G42: 0.035 | H42: 0.033 | I42: 0.03 | J42: 0.03 | K42: 0.03 | L42: 0.03 | M42: 0.03
B43: Market Rent $/SF — by year (calc): | D43: Year 1 | E43: Year 2 | F43: Year 3 | G43: Year 4 | H43: Year 5 | I43: Year 6 | J43: Year 7 | K43: Year 8 | L43: Year 9 | M43: Year 10
D44: =C38 -> 10 | E44: =D44*(1+D42) -> 10.6 | F44: =E44*(1+E42) -> 11.077 | G44: =F44*(1+F42) -> 11.575465 | H44: =G44*(1+G42) -> 11.980606 | I44: =H44*(1+H42) -> 12.375966 | J44: =I44*(1+I42) -> 12.747245 | K44: =J44*(1+J42) -> 13.129663 | L44: =K44*(1+K42) -> 13.523553 | M44: =L44*(1+L42) -> 13.929259
B46: LEASING ASSUMPTIONS (Second-Generation)
B47: Tenant Improvements — New ($/SF) | C47: 5
B48: Tenant Improvements — Renewal ($/SF) | C48: 1.5
...

Sheet Rent Roll
B2: RENT ROLL — MONTHLY TENANT BUILD
B3: Each tenant row projects monthly rent contribution over 120 months. Columns N-V are calculated helper fields.
B5: Month # | Y5: 1 | Z5: 2 | AA5: 3 | AB5: 4 | AC5: 5 | AD5: 6 | AE5: 7 | AF5: 8 | AG5: 9 | AH5: 10 | AI5: 11 | AJ5: 12 | AK5: 13 | AL5: 14 | AM5: 15 | AN5: 16 | AO5: 17 | AP5: 18 | AQ5: 19 | AR5: 20 | AS5: 21 | AT5: 22 | AU5: 23 | AV5: 24 | AW5: 25 | AX5: 26 | AY5: 27 | AZ5: 28 | BA5: 29 | BB5: 30 | BC5: 31 | BD5: 32 | BE5: 33 | BF5: 34 | BG5: 35 | BH5: 36 | BI5: 37 | BJ5: 38 | BK5: 39 | BL5: 40 | BM5: 41 | BN5: 42 | BO5: 43 | BP5: 44 | BQ5: 45 | BR5: 46 | BS5: 47 | BT5: 48 | BU5: 49 | BV5: 50 | BW5: 51 | BX5: 52 | BY5: 53 | BZ5: 54 | CA5: 55 | CB5: 56 | CC5: 57 | CD5: 58 | CE5: 59 | CF5: 60 | CG5: 61 | CH5: 62 | CI5: 63 | CJ5: 64 | CK5: 65 | CL5: 66 | CM5: 67 | CN5: 68 | CO5: 69 | CP5: 70 | CQ5: 71 | CR5: 72 | CS5: 73 | CT5: 74 | CU5: 75 | CV5: 76 | CW5: 77 | CX5: 78 | CY5: 79 | CZ5: 80 | DA5: 81 | DB5: 82 | DC5: 83 | DD5: 84 | DE5: 85 | DF5: 86 | DG5: 87 | DH5: 88 | DI5: 89 | DJ5: 90 | DK5: 91 | DL5: 92 | DM5: 93 | DN5: 94 | DO5: 95 | DP5: 96 | DQ5: 97 | DR5: 98 | DS5: 99 | DT5: 100 | DU5: 101 | DV5: 102 | DW5: 103 | DX5: 104 | DY5: 105 | DZ5: 106 | EA5: 107 | EB5: 108 | EC5: 109 | ED5: 110 | EE5: 111 | EF5: 112 | EG5: 113 | EH5: 114 | EI5: 115 | EJ5: 116 | EK5: 117 | EL5: 118 | EM5: 119 | EN5: 120
B6: Year # | Y6: =CEILING(Y5/12,1) -> 1 | Z6: =CEILING(Z5/12,1) -> 1 | AA6: =CEILING(AA5/12,1) -> 1 | AB6: =CEILING(AB5/12,1) -> 1 | AC6: =CEILING(AC5/12,1) -> 1 | AD6: =CEILING(AD5/12,1) -> 1 | AE6: =CEILING(AE5/12,1) -> 1 | AF6: =CEILING(AF5/12,1) -> 1 | ... EN6: =CEILING(EN5/12,1) -> 10
B7: Market Rent $/SF (annualized) | Y7: =INDEX(MktRentSchedule,Y6) -> 10 | Z7: =INDEX(MktRentSchedule,Z6) -> 10 | AA7: =INDEX(MktRentSchedule,AA6) -> 10 | AB7: =INDEX(MktRentSchedule,AB6) -> 10 | AC7: =INDEX(MktRentSchedule,AC6) -> 10 | AD7: =INDEX(MktRentSchedule,AD6) -> 10 | AE7: =INDEX(MktRentSchedule,AE6) -> 10 | AF7: =INDEX(MktRentSchedule,AF6) -> 10 | ... EN7: =INDEX(MktRentSchedule,EN6) -> 13.929259
B9: Suite | C9: Tenant Name | D9: SF | E9: % of Prop | F9: Lease Start | G9: Lease End | H9: Rent PSF | I9: Annual Rent | J9: Esc % | K9: Recovery | L9: Mkt $/SF | M9: Action | N9: Lease Start Mo | O9: Lease End Mo | P9: Rollover Month | Q9: Downtime Mo | R9: Re-Lease Start Mo | S9: Free Rent Mo | T9: Rent-Pay Start Mo | U9: Release Year | V9: Tenant Improvements | W9: Leasing Commissions | X9: Release PSF | Y9: M1 | Z9: M2 | AA9: M3 | AB9: M4 | AC9: M5 | AD9: M6 | AE9: M7 | AF9: M8 | AG9: M9 | AH9: M10 | AI9: M11 | AJ9: M12 | AK9: M13 | AL9: M14 | AM9: M15 | AN9: M16 | AO9: M17 | AP9: M18 | AQ9: M19 | AR9: M20 | AS9: M21 | AT9: M22 | AU9: M23 | AV9: M24 | AW9: M25 | AX9: M26 | AY9: M27 | AZ9: M28 | BA9: M29 | BB9: M30 | BC9: M31 | BD9: M32 | BE9: M33 | BF9: M34 | BG9: M35 | BH9: M36 | BI9: M37 | BJ9: M38 | BK9: M39 | BL9: M40 | BM9: M41 | BN9: M42 | BO9: M43 | BP9: M44 | BQ9: M45 | BR9: M46 | BS9: M47 | BT9: M48 | BU9: M49 | BV9: M50 | BW9: M51 | BX9: M52 | BY9: M53 | BZ9: M54 | CA9: M55 | CB9: M56 | CC9: M57 | CD9: M58 | CE9: M59 | CF9: M60 | CG9: M61 | CH9: M62 | CI9: M63 | CJ9: M64 | CK9: M65 | CL9: M66 | CM9: M67 | CN9: M68 | CO9: M69 | CP9: M70 | CQ9: M71 | CR9: M72 | CS9: M73 | CT9: M74 | CU9: M75 | CV9: M76 | CW9: M77 | CX9: M78 | CY9: M79 | CZ9: M80 | DA9: M81 | DB9: M82 | DC9: M83 | DD9: M84 | DE9: M85 | DF9: M86 | DG9: M87 | DH9: M88 | DI9: M89 | DJ9: M90 | DK9: M91 | DL9: M92 | DM9: M93 | DN9: M94 | DO9: M95 | DP9: M96 | DQ9: M97 | DR9: M98 | DS9: M99 | DT9: M100 | DU9: M101 | DV9: M102 | DW9: M103 | DX9: M104 | DY9: M105 | DZ9: M106 | EA9: M107 | EB9: M108 | EC9: M109 | ED9: M110 | EE9: M111 | EF9: M112 | EG9: M113 | EH9: M114 | EI9: M115 | EJ9: M116 | EK9: M117 | EL9: M118 | EM9: M119 | EN9: M120
B10: 204 | C10: Aqua Essentials | D10: 14400 | E10: =IFERROR(D10/TotalSF,0) -> 0.011873351 | F10: 43770 | G10: 46357 | H10: 10.71 | I10: =IFERROR(D10*H10,0) -> 154224 | J10: 0.03 | K10: NNN | L10: 13 | M10: Renew | N10: =IF(F10="",0,(YEAR(F10)-YEAR(AnalysisStart))*12+(MONTH(F10)-MONTH(AnalysisStart))+1) -> -49 | O10: =IF(G10="",0,(YEAR(G10)-YEAR(AnalysisStart))*12+(MONTH(G10)-MONTH(AnalysisStart))+1) -> 36 | P10: =IF(D10="",0,MAX(1,O10+1)) -> 37 | Q10: =IF(D10="",0,Downtime_Ren*Retention_Ratio+Downtime_New*(1-Retention_Ratio)) -> 3 | R10: =IF(D10="",0,MIN(120,P10+Q10)) -> 40 | S10: =IF(D10="",0,FreeRent_New*(1-Retention_Ratio)+FreeRent_Ren*Retention_Ratio) -> 1 | T10: =IF(D10="",0,MIN(121,R10+S10)) -> 41 | U10: =IF(D10="",0,MIN(10,MAX(1,CEILING(R10/12,1)))) -> 4 | V10: =IF(D10="",0,(Retention_Ratio*TI_Ren+(1-Retention_Ratio)*TI_New)*D10) -> 34200 | W10: =IF(D10="",0,Retention_Ratio*LC_Ren*LeaseTermYrs*'Rent Roll'!D10*'Rent Roll'!X10+(1-Retention_Ratio)*LC_Ren*LeaseTermYrs*'Rent Roll'!D10*'Rent Roll'!X10) -> 32503.906 | X10: =IF(D10="",0,L10*INDEX(MktRentSchedule,U10)/MktRentY1) -> 15.048104 | Y10: =IF($D10="",0,IF(Y$5<$N10,0,IF(Y$5<=$O10,$D10*$H10*(1+$J10)^FLOOR((Y$5-1)/12,1)/12,IF(Y$5<$T10,0,$D10*$X10*(1+$J10)^FLOOR((Y$5-$R10)/12,1)/12)))) -> 12852 | Z10: =IF($D10="",0,IF(Z$5<$N10,0,IF(Z$5<=$O10,$D10*$H10*(1+$J10)^FLOOR((Z$5-1)/12,1)/12,IF(Z$5<$T10,0,$D10*$X10*(1+$J10)^FLOOR((Z$5-$R10)/12,1)/12)))) -> 12852 | AA10: =IF($D10="",0,IF(AA$5<$N10,0,IF(AA$5<=$O10,$D10*$H10*(1+$J10)^FLOOR((AA$5-1)/12,1)/12,IF(AA$5<$T10,0,$D10*$X10*(1+$J10)^FLOOR((AA$5-$R10)/12,1)/12)))) -> 12852 | AB10: =IF($D10="",0,IF(AB$5<$N10,0,IF(AB$5<=$O10,$D10*$H10*(1+$J10)^FLOOR((AB$5-1)/12,1)/12,IF(AB$5<$T10,0,$D10*$X10*(1+$J10)^FLOOR((AB$5-$R10)/12,1)/12)))) -> 12852 | AC10: =IF($D10="",0,IF(AC$5<$N10,0,IF(AC$5<=$O10,$D10*$H10*(1+$J10)^FLOOR((AC$5-1)/12,1)/12,IF(AC$5<$T10,0,$D10*$X10*(1+$J10)^FLOOR((AC$5-$R10)/12,1)/12)))) -> 12852 | AD10: =IF($D10="",0,IF(AD$5<$N10,0,IF(AD$5<=$O10,$D10*$H10*(1+$J10)^FLOOR((AD$5-1)/12,1)/12,IF(AD$5<$T10,0,$D10*$X10*(1+$J10)^FLOOR((AD$5-$R10)/12,1)/12)))) -> 12852 | AE10: =IF($D10="",0,IF(AE$5<$N10,0,IF(AE$5<=$O10,$D10*$H10*(1+$J10)^FLOOR((AE$5-1)/12,1)/12,IF(AE$5<$T10,0,$D10*$X10*(1+$J10)^FLOOR((AE$5-$R10)/12,1)/12)))) -> 12852 | AF10: =IF($D10="",0,IF(AF$5<$N10,0,IF(AF$5<=$O10,$D10*$H10*(1+$J10)^FLOOR((AF$5-1)/12,1)/12,IF(AF$5<$T10,0,$D10*$X10*(1+$J10)^FLOOR((AF$5-$R10)/12,1)/12)))) -> 12852 | ... EN10: =IF($D10="",0,IF(EN$5<$N10,0,IF(EN$5<=$O10,$D10*$H10*(1+$J10)^FLOOR((EN$5-1)/12,1)/12,IF(EN$5<$T10,0,$D10*$X10*(1+$J10)^FLOOR((EN$5-$R10)/12,1)/12)))) -> 21561.868
B11: 205 | C11: White Glove Delivery | D11: 17636 | E11: =IFERROR(D11/TotalSF,0) -> 0.014541557 | F11: 44440 | G11: 46966 | H11: 7.69 | I11: =IFERROR(D11*H11,0) -> 135620.84 | J11: 0.03 | K11: NNN | L11: 13 | M11: Renew | N11: =IF(F11="",0,(YEAR(F11)-YEAR(AnalysisStart))*12+(MONTH(F11)-MONTH(AnalysisStart))+1) -> -27 | O11: =IF(G11="",0,(YEAR(G11)-YEAR(AnalysisStart))*12+(MONTH(G11)-MONTH(AnalysisStart))+1) -> 56 | P11: =IF(D11="",0,MAX(1,O11+1)) -> 57 | Q11: =IF(D11="",0,Downtime_Ren*Retention_Ratio+Downtime_New*(1-Retention_Ratio)) -> 3 | R11: =IF(D11="",0,MIN(120,P11+Q11)) -> 60 | S11: =IF(D11="",0,FreeRent_New*(1-Retention_Ratio)+FreeRent_Ren*Retention_Ratio) -> 1 | T11: =IF(D11="",0,MIN(121,R11+S11)) -> 61 | U11: =IF(D11="",0,MIN(10,MAX(1,CEILING(R11/12,1)))) -> 5 | V11: =IF(D11="",0,(Retention_Ratio*TI_Ren+(1-Retention_Ratio)*TI_New)*D11) -> 41885.5 | W11: =IF(D11="",0,Retention_Ratio*LC_Ren*LeaseTermYrs*'Rent Roll'!D11*'Rent Roll'!X11+(1-Retention_Ratio)*LC_Ren*LeaseTermYrs*'Rent Roll'!D11*'Rent Roll'!X11) -> 41201.545 | X11: =IF(D11="",0,L11*INDEX(MktRentSchedule,U11)/MktRentY1) -> 15.574788 | Y11: =IF($D11="",0,IF(Y$5<$N11,0,IF(Y$5<=$O11,$D11*$H11*(1+$J11)^FLOOR((Y$5-1)/12,1)/12,IF(Y$5<$T11,0,$D11*$X11*(1+$J11)^FLOOR((Y$5-$R11)/12,1)/12)))) -> 11301.737 | Z11: =IF($D11="",0,IF(Z$5<$N11,0,IF(Z$5<=$O11,$D11*$H11*(1+$J11)^FLOOR((Z$5-1)/12,1)/12,IF(Z$5<$T11,0,$D11*$X11*(1+$J11)^FLOOR((Z$5-$R11)/12,1)/12)))) -> 11301.737 | AA11: =IF($D11="",0,IF(AA$5<$N11,0,IF(AA$5<=$O11,$D11*$H11*(1+$J11)^FLOOR((AA$5-1)/12,1)/12,IF(AA$5<$T11,0,$D11*$X11*(1+$J11)^FLOOR((AA$5-$R11)/12,1)/12)))) -> 11301.737 | AB11: =IF($D11="",0,IF(AB$5<$N11,0,IF(AB$5<=$O11,$D11*$H11*(1+$J11)^FLOOR((AB$5-1)/12,1)/12,IF(AB$5<$T11,0,$D11*$X11*(1+$J11)^FLOOR((AB$5-$R11)/12,1)/12)))) -> 11301.737 | AC11: =IF($D11="",0,IF(AC$5<$N11,0,IF(AC$5<=$O11,$D11*$H11*(1+$J11)^FLOOR((AC$5-1)/12,1)/12,IF(AC$5<$T11,0,$D11*$X11*(1+$J11)^FLOOR((AC$5-$R11)/12,1)/12)))) -> 11301.737 | AD11: =IF($D11="",0,IF(AD$5<$N11,0,IF(AD$5<=$O11,$D11*$H11*(1+$J11)^FLOOR((AD$5-1)/12,1)/12,IF(AD$5<$T11,0,$D11*$X11*(1+$J11)^FLOOR((AD$5-$R11)/12,1)/12)))) -> 11301.737 | AE11: =IF($D11="",0,IF(AE$5<$N11,0,IF(AE$5<=$O11,$D11*$H11*(1+$J11)^FLOOR((AE$5-1)/12,1)/12,IF(AE$5<$T11,0,$D11*$X11*(1+$J11)^FLOOR((AE$5-$R11)/12,1)/12)))) -> 11301.737 | AF11: =IF($D11="",0,IF(AF$5<$N11,0,IF(AF$5<=$O11,$D11*$H11*(1+$J11)^FLOOR((AF$5-1)/12,1)/12,IF(AF$5<$T11,0,$D11*$X11*(1+$J11)^FLOOR((AF$5-$R11)/12,1)/12)))) -> 11301.737 | ... EN11: =IF($D11="",0,IF(EN$5<$N11,0,IF(EN$5<=$O11,$D11*$H11*(1+$J11)^FLOOR((EN$5-1)/12,1)/12,IF(EN$5<$T11,0,$D11*$X11*(1+$J11)^FLOOR((EN$5-$R11)/12,1)/12)))) -> 26535.49
B12: 208 | C12: NISOLO, LLC | D12: 18364 | E12: =IFERROR(D12/TotalSF,0) -> 0.015141821 | F12: 43252 | G12: 46204 | H12: 7.43 | I12: =IFERROR(D12*H12,0) -> 136444.52 | J12: 0.03 | K12: NNN | L12: 13 | M12: Renew | N12: =IF(F12="",0,(YEAR(F12)-YEAR(AnalysisStart))*12+(MONTH(F12)-MONTH(AnalysisStart))+1) -> -66 | O12: =IF(G12="",0,(YEAR(G12)-YEAR(AnalysisStart))*12+(MONTH(G12)-MONTH(AnalysisStart))+1) -> 31 | P12: =IF(D12="",0,MAX(1,O12+1)) -> 32 | Q12: =IF(D12="",0,Downtime_Ren*Retention_Ratio+Downtime_New*(1-Retention_Ratio)) -> 3 | R12: =IF(D12="",0,MIN(120,P12+Q12)) -> 35 | S12: =IF(D12="",0,FreeRent_New*(1-Retention_Ratio)+FreeRent_Ren*Retention_Ratio) -> 1 | T12: =IF(D12="",0,MIN(121,R12+S12)) -> 36 | U12: =IF(D12="",0,MIN(10,MAX(1,CEILING(R12/12,1)))) -> 3 | V12: =IF(D12="",0,(Retention_Ratio*TI_Ren+(1-Retention_Ratio)*TI_New)*D12) -> 43614.5 | W12: =IF(D12="",0,Retention_Ratio*LC_Ren*LeaseTermYrs*'Rent Roll'!D12*'Rent Roll'!X12+(1-Retention_Ratio)*LC_Ren*LeaseTermYrs*'Rent Roll'!D12*'Rent Roll'!X12) -> 39666.515 | X12: =IF(D12="",0,L12*INDEX(MktRentSchedule,U12)/MktRentY1) -> 14.4001 | Y12: =IF($D12="",0,IF(Y$5<$N12,0,IF(Y$5<=$O12,$D12*$H12*(1+$J12)^FLOOR((Y$5-1)/12,1)/12,IF(Y$5<$T12,0,$D12*$X12*(1+$J12)^FLOOR((Y$5-$R12)/12,1)/12)))) -> 11370.377 | Z12: =IF($D12="",0,IF(Z$5<$N12,0,IF(Z$5<=$O12,$D12*$H12*(1+$J12)^FLOOR((Z$5-1)/12,1)/12,IF(Z$5<$T12,0,$D12*$X12*(1+$J12)^FLOOR((Z$5-$R12)/12,1)/12)))) -> 11370.377 | AA12: =IF($D12="",0,IF(AA$5<$N12,0,IF(AA$5<=$O12,$D12*$H12*(1+$J12)^FLOOR((AA$5-1)/12,1)/12,IF(AA$5<$T12,0,$D12*$X12*(1+$J12)^FLOOR((AA$5-$R12)/12,1)/12)))) -> 11370.377 | AB12: =IF($D12="",0,IF(AB$5<$N12,0,IF(AB$5<=$O12,$D12*$H12*(1+$J12)^FLOOR((AB$5-1)/12,1)/12,IF(AB$5<$T12,0,$D12*$X12*(1+$J12)^FLOOR((AB$5-$R12)/12,1)/12)))) -> 11370.377 | AC12: =IF($D12="",0,IF(AC$5<$N12,0,IF(AC$5<=$O12,$D12*$H12*(1+$J12)^FLOOR((AC$5-1)/12,1)/12,IF(AC$5<$T12,0,$D12*$X12*(1+$J12)^FLOOR((AC$5-$R12)/12,1)/12)))) -> 11370.377 | AD12: =IF($D12="",0,IF(AD$5<$N12,0,IF(AD$5<=$O12,$D12*$H12*(1+$J12)^FLOOR((AD$5-1)/12,1)/12,IF(AD$5<$T12,0,$D12*$X12*(1+$J12)^FLOOR((AD$5-$R12)/12,1)/12)))) -> 11370.377 | AE12: =IF($D12="",0,IF(AE$5<$N12,0,IF(AE$5<=$O12,$D12*$H12*(1+$J12)^FLOOR((AE$5-1)/12,1)/12,IF(AE$5<$T12,0,$D12*$X12*(1+$J12)^FLOOR((AE$5-$R12)/12,1)/12)))) -> 11370.377 | AF12: =IF($D12="",0,IF(AF$5<$N12,0,IF(AF$5<=$O12,$D12*$H12*(1+$J12)^FLOOR((AF$5-1)/12,1)/12,IF(AF$5<$T12,0,$D12*$X12*(1+$J12)^FLOOR((AF$5-$R12)/12,1)/12)))) -> 11370.377 | ... EN12: =IF($D12="",0,IF(EN$5<$N12,0,IF(EN$5<=$O12,$D12*$H12*(1+$J12)^FLOOR((EN$5-1)/12,1)/12,IF(EN$5<$T12,0,$D12*$X12*(1+$J12)^FLOOR((EN$5-$R12)/12,1)/12)))) -> 27102.673
B13: 215 | C13: Five Star Food Service | D13: 10800 | E13: =IFERROR(D13/TotalSF,0) -> 0.0089050132 | F13: 44774 | G13: 45839 | H13: 9.32 | I13: =IFERROR(D13*H13,0) -> 100656 | J13: 0.035 | K13: NNN | L13: 13 | M13: Renew | N13: =IF(F13="",0,(YEAR(F13)-YEAR(AnalysisStart))*12+(MONTH(F13)-MONTH(AnalysisStart))+1) -> -16 | O13: =IF(G13="",0,(YEAR(G13)-YEAR(AnalysisStart))*12+(MONTH(G13)-MONTH(AnalysisStart))+1) -> 19 | P13: =IF(D13="",0,MAX(1,O13+1)) -> 20 | Q13: =IF(D13="",0,Downtime_Ren*Retention_Ratio+Downtime_New*(1-Retention_Ratio)) -> 3 | R13: =IF(D13="",0,MIN(120,P13+Q13)) -> 23 | S13: =IF(D13="",0,FreeRent_New*(1-Retention_Ratio)+FreeRent_Ren*Retention_Ratio) -> 1 | T13: =IF(D13="",0,MIN(121,R13+S13)) -> 24 | U13: =IF(D13="",0,MIN(10,MAX(1,CEILING(R13/12,1)))) -> 2 | V13: =IF(D13="",0,(Retention_Ratio*TI_Ren+(1-Retention_Ratio)*TI_New)*D13) -> 25650 | W13: =IF(D13="",0,Retention_Ratio*LC_Ren*LeaseTermYrs*'Rent Roll'!D13*'Rent Roll'!X13+(1-Retention_Ratio)*LC_Ren*LeaseTermYrs*'Rent Roll'!D13*'Rent Roll'!X13) -> 22323.6 | X13: =IF(D13="",0,L13*INDEX(MktRentSchedule,U13)/MktRentY1) -> 13.78 | Y13: =IF($D13="",0,IF(Y$5<$N13,0,IF(Y$5<=$O13,$D13*$H13*(1+$J13)^FLOOR((Y$5-1)/12,1)/12,IF(Y$5<$T13,0,$D13*$X13*(1+$J13)^FLOOR((Y$5-$R13)/12,1)/12)))) -> 8388 | Z13: =IF($D13="",0,IF(Z$5<$N13,0,IF(Z$5<=$O13,$D13*$H13*(1+$J13)^FLOOR((Z$5-1)/12,1)/12,IF(Z$5<$T13,0,$D13*$X13*(1+$J13)^FLOOR((Z$5-$R13)/12,1)/12)))) -> 8388 | AA13: =IF($D13="",0,IF(AA$5<$N13,0,IF(AA$5<=$O13,$D13*$H13*(1+$J13)^FLOOR((AA$5-1)/12,1)/12,IF(AA$5<$T13,0,$D13*$X13*(1+$J13)^FLOOR((AA$5-$R13)/12,1)/12)))) -> 8388 | AB13: =IF($D13="",0,IF(AB$5<$N13,0,IF(AB$5<=$O13,$D13*$H13*(1+$J13)^FLOOR((AB$5-1)/12,1)/12,IF(AB$5<$T13,0,$D13*$X13*(1+$J13)^FLOOR((AB$5-$R13)/12,1)/12)))) -> 8388 | AC13: =IF($D13="",0,IF(AC$5<$N13,0,IF(AC$5<=$O13,$D13*$H13*(1+$J13)^FLOOR((AC$5-1)/12,1)/12,IF(AC$5<$T13,0,$D13*$X13*(1+$J13)^FLOOR((AC$5-$R13)/12,1)/12)))) -> 8388 | AD13: =IF($D13="",0,IF(AD$5<$N13,0,IF(AD$5<=$O13,$D13*$H13*(1+$J13)^FLOOR((AD$5-1)/12,1)/12,IF(AD$5<$T13,0,$D13*$X13*(1+$J13)^FLOOR((AD$5-$R13)/12,1)/12)))) -> 8388 | AE13: =IF($D13="",0,IF(AE$5<$N13,0,IF(AE$5<=$O13,$D13*$H13*(1+$J13)^FLOOR((AE$5-1)/12,1)/12,IF(AE$5<$T13,0,$D13*$X13*(1+$J13)^FLOOR((AE$5-$R13)/12,1)/12)))) -> 8388 | AF13: =IF($D13="",0,IF(AF$5<$N13,0,IF(AF$5<=$O13,$D13*$H13*(1+$J13)^FLOOR((AF$5-1)/12,1)/12,IF(AF$5<$T13,0,$D13*$X13*(1+$J13)^FLOOR((AF$5-$R13)/12,1)/12)))) -> 8388 | ... EN13: =IF($D13="",0,IF(EN$5<$N13,0,IF(EN$5<=$O13,$D13*$H13*(1+$J13)^FLOOR((EN$5-1)/12,1)/12,IF(EN$5<$T13,0,$D13*$X13*(1+$J13)^FLOOR((EN$5-$R13)/12,1)/12)))) -> 16331.066
B14: 218 | C14: Kennedy Performance | D14: 7200 | E14: =IFERROR(D14/TotalSF,0) -> 0.0059366755 | F14: 44562 | G14: 46419 | H14: 8.76 | I14: =IFERROR(D14*H14,0) -> 63072 | J14: 0.03 | K14: NNN | L14: 13 | M14: Renew | N14: =IF(F14="",0,(YEAR(F14)-YEAR(AnalysisStart))*12+(MONTH(F14)-MONTH(AnalysisStart))+1) -> -23 | O14: =IF(G14="",0,(YEAR(G14)-YEAR(AnalysisStart))*12+(MONTH(G14)-MONTH(AnalysisStart))+1) -> 38 | P14: =IF(D14="",0,MAX(1,O14+1)) -> 39 | Q14: =IF(D14="",0,Downtime_Ren*Retention_Ratio+Downtime_New*(1-Retention_Ratio)) -> 3 | R14: =IF(D14="",0,MIN(120,P14+Q14)) -> 42 | S14: =IF(D14="",0,FreeRent_New*(1-Retention_Ratio)+FreeRent_Ren*Retention_Ratio) -> 1 | T14: =IF(D14="",0,MIN(121,R14+S14)) -> 43 | U14: =IF(D14="",0,MIN(10,MAX(1,CEILING(R14/12,1)))) -> 4 | V14: =IF(D14="",0,(Retention_Ratio*TI_Ren+(1-Retention_Ratio)*TI_New)*D14) -> 17100 | W14: =IF(D14="",0,Retention_Ratio*LC_Ren*LeaseTermYrs*'Rent Roll'!D14*'Rent Roll'!X14+(1-Retention_Ratio)*LC_Ren*LeaseTermYrs*'Rent Roll'!D14*'Rent Roll'!X14) -> 16251.953 | X14: =IF(D14="",0,L14*INDEX(MktRentSchedule,U14)/MktRentY1) -> 15.048104 | Y14: =IF($D14="",0,IF(Y$5<$N14,0,IF(Y$5<=$O14,$D14*$H14*(1+$J14)^FLOOR((Y$5-1)/12,1)/12,IF(Y$5<$T14,0,$D14*$X14*(1+$J14)^FLOOR((Y$5-$R14)/12,1)/12)))) -> 5256 | Z14: =IF($D14="",0,IF(Z$5<$N14,0,IF(Z$5<=$O14,$D14*$H14*(1+$J14)^FLOOR((Z$5-1)/12,1)/12,IF(Z$5<$T14,0,$D14*$X14*(1+$J14)^FLOOR((Z$5-$R14)/12,1)/12)))) -> 5256 | AA14: =IF($D14="",0,IF(AA$5<$N14,0,IF(AA$5<=$O14,$D14*$H14*(1+$J14)^FLOOR((AA$5-1)/12,1)/12,IF(AA$5<$T14,0,$D14*$X14*(1+$J14)^FLOOR((AA$5-$R14)/12,1)/12)))) -> 5256 | AB14: =IF($D14="",0,IF(AB$5<$N14,0,IF(AB$5<=$O14,$D14*$H14*(1+$J14)^FLOOR((AB$5-1)/12,1)/12,IF(AB$5<$T14,0,$D14*$X14*(1+$J14)^FLOOR((AB$5-$R14)/12,1)/12)))) -> 5256 | AC14: =IF($D14="",0,IF(AC$5<$N14,0,IF(AC$5<=$O14,$D14*$H14*(1+$J14)^FLOOR((AC$5-1)/12,1)/12,IF(AC$5<$T14,0,$D14*$X14*(1+$J14)^FLOOR((AC$5-$R14)/12,1)/12)))) -> 5256 | AD14: =IF($D14="",0,IF(AD$5<$N14,0,IF(AD$5<=$O14,$D14*$H14*(1+$J14)^FLOOR((AD$5-1)/12,1)/12,IF(AD$5<$T14,0,$D14*$X14*(1+$J14)^FLOOR((AD$5-$R14)/12,1)/12)))) -> 5256 | AE14: =IF($D14="",0,IF(AE$5<$N14,0,IF(AE$5<=$O14,$D14*$H14*(1+$J14)^FLOOR((AE$5-1)/12,1)/12,IF(AE$5<$T14,0,$D14*$X14*(1+$J14)^FLOOR((AE$5-$R14)/12,1)/12)))) -> 5256 | AF14: =IF($D14="",0,IF(AF$5<$N14,0,IF(AF$5<=$O14,$D14*$H14*(1+$J14)^FLOOR((AF$5-1)/12,1)/12,IF(AF$5<$T14,0,$D14*$X14*(1+$J14)^FLOOR((AF$5-$R14)/12,1)/12)))) -> 5256 | ... EN14: =IF($D14="",0,IF(EN$5<$N14,0,IF(EN$5<=$O14,$D14*$H14*(1+$J14)^FLOOR((EN$5-1)/12,1)/12,IF(EN$5<$T14,0,$D14*$X14*(1+$J14)^FLOOR((EN$5-$R14)/12,1)/12)))) -> 10780.934
B15: 220 | C15: MPH Global | D15: 7200 | E15: =IFERROR(D15/TotalSF,0) -> 0.0059366755 | F15: 44593 | G15: 45658 | H15: 8.58 | I15: =IFERROR(D15*H15,0) -> 61776 | J15: 0.04 | K15: NNN | L15: 13 | M15: Vacate | N15: =IF(F15="",0,(YEAR(F15)-YEAR(AnalysisStart))*12+(MONTH(F15)-MONTH(AnalysisStart))+1) -> -22 | O15: =IF(G15="",0,(YEAR(G15)-YEAR(AnalysisStart))*12+(MONTH(G15)-MONTH(AnalysisStart))+1) -> 13 | P15: =IF(D15="",0,MAX(1,O15+1)) -> 14 | Q15: =IF(D15="",0,Downtime_Ren*Retention_Ratio+Downtime_New*(1-Retention_Ratio)) -> 3 | R15: =IF(D15="",0,MIN(120,P15+Q15)) -> 17 | S15: =IF(D15="",0,FreeRent_New*(1-Retention_Ratio)+FreeRent_Ren*Retention_Ratio) -> 1 | T15: =IF(D15="",0,MIN(121,R15+S15)) -> 18 | U15: =IF(D15="",0,MIN(10,MAX(1,CEILING(R15/12,1)))) -> 2 | V15: =IF(D15="",0,(Retention_Ratio*TI_Ren+(1-Retention_Ratio)*TI_New)*D15) -> 17100 | W15: =IF(D15="",0,Retention_Ratio*LC_Ren*LeaseTermYrs*'Rent Roll'!D15*'Rent Roll'!X15+(1-Retention_Ratio)*LC_Ren*LeaseTermYrs*'Rent Roll'!D15*'Rent Roll'!X15) -> 14882.4 | X15: =IF(D15="",0,L15*INDEX(MktRentSchedule,U15)/MktRentY1) -> 13.78 | Y15: =IF($D15="",0,IF(Y$5<$N15,0,IF(Y$5<=$O15,$D15*$H15*(1+$J15)^FLOOR((Y$5-1)/12,1)/12,IF(Y$5<$T15,0,$D15*$X15*(1+$J15)^FLOOR((Y$5-$R15)/12,1)/12)))) -> 5148 | Z15: =IF($D15="",0,IF(Z$5<$N15,0,IF(Z$5<=$O15,$D15*$H15*(1+$J15)^FLOOR((Z$5-1)/12,1)/12,IF(Z$5<$T15,0,$D15*$X15*(1+$J15)^FLOOR((Z$5-$R15)/12,1)/12)))) -> 5148 | AA15: =IF($D15="",0,IF(AA$5<$N15,0,IF(AA$5<=$O15,$D15*$H15*(1+$J15)^FLOOR((AA$5-1)/12,1)/12,IF(AA$5<$T15,0,$D15*$X15*(1+$J15)^FLOOR((AA$5-$R15)/12,1)/12)))) -> 5148 | AB15: =IF($D15="",0,IF(AB$5<$N15,0,IF(AB$5<=$O15,$D15*$H15*(1+$J15)^FLOOR((AB$5-1)/12,1)/12,IF(AB$5<$T15,0,$D15*$X15*(1+$J15)^FLOOR((AB$5-$R15)/12,1)/12)))) -> 5148 | AC15: =IF($D15="",0,IF(AC$5<$N15,0,IF(AC$5<=$O15,$D15*$H15*(1+$J15)^FLOOR((AC$5-1)/12,1)/12,IF(AC$5<$T15,0,$D15*$X15*(1+$J15)^FLOOR((AC$5-$R15)/12,1)/12)))) -> 5148 | AD15: =IF($D15="",0,IF(AD$5<$N15,0,IF(AD$5<=$O15,$D15*$H15*(1+$J15)^FLOOR((AD$5-1)/12,1)/12,IF(AD$5<$T15,0,$D15*$X15*(1+$J15)^FLOOR((AD$5-$R15)/12,1)/12)))) -> 5148 | AE15: =IF($D15="",0,IF(AE$5<$N15,0,IF(AE$5<=$O15,$D15*$H15*(1+$J15)^FLOOR((AE$5-1)/12,1)/12,IF(AE$5<$T15,0,$D15*$X15*(1+$J15)^FLOOR((AE$5-$R15)/12,1)/12)))) -> 5148 | AF15: =IF($D15="",0,IF(AF$5<$N15,0,IF(AF$5<=$O15,$D15*$H15*(1+$J15)^FLOOR((AF$5-1)/12,1)/12,IF(AF$5<$T15,0,$D15*$X15*(1+$J15)^FLOOR((AF$5-$R15)/12,1)/12)))) -> 5148 | ... EN15: =IF($D15="",0,IF(EN$5<$N15,0,IF(EN$5<=$O15,$D15*$H15*(1+$J15)^FLOOR((EN$5-1)/12,1)/12,IF(EN$5<$T15,0,$D15*$X15*(1+$J15)^FLOOR((EN$5-$R15)/12,1)/12)))) -> 11315.329
B16: 223 | C16: Axis Portable Air | D16: 7200 | E16: =IFERROR(D16/TotalSF,0) -> 0.0059366755 | F16: 44621 | G16: 45717 | H16: 8.84 | I16: =IFERROR(D16*H16,0) -> 63648 | J16: 0.04 | K16: NNN | L16: 13 | M16: Renew | N16: =IF(F16="",0,(YEAR(F16)-YEAR(AnalysisStart))*12+(MONTH(F16)-MONTH(AnalysisStart))+1) -> -21 | O16: =IF(G16="",0,(YEAR(G16)-YEAR(AnalysisStart))*12+(MONTH(G16)-MONTH(AnalysisStart))+1) -> 15 | P16: =IF(D16="",0,MAX(1,O16+1)) -> 16 | Q16: =IF(D16="",0,Downtime_Ren*Retention_Ratio+Downtime_New*(1-Retention_Ratio)) -> 3 | R16: =IF(D16="",0,MIN(120,P16+Q16)) -> 19 | S16: =IF(D16="",0,FreeRent_New*(1-Retention_Ratio)+FreeRent_Ren*Retention_Ratio) -> 1 | T16: =IF(D16="",0,MIN(121,R16+S16)) -> 20 | U16: =IF(D16="",0,MIN(10,MAX(1,CEILING(R16/12,1)))) -> 2 | V16: =IF(D16="",0,(Retention_Ratio*TI_Ren+(1-Retention_Ratio)*TI_New)*D16) -> 17100 | W16: =IF(D16="",0,Retention_Ratio*LC_Ren*LeaseTermYrs*'Rent Roll'!D16*'Rent Roll'!X16+(1-Retention_Ratio)*LC_Ren*LeaseTermYrs*'Rent Roll'!D16*'Rent Roll'!X16) -> 14882.4 | X16: =IF(D16="",0,L16*INDEX(MktRentSchedule,U16)/MktRentY1) -> 13.78 | Y16: =IF($D16="",0,IF(Y$5<$N16,0,IF(Y$5<=$O16,$D16*$H16*(1+$J16)^FLOOR((Y$5-1)/12,1)/12,IF(Y$5<$T16,0,$D16*$X16*(1+$J16)^FLOOR((Y$5-$R16)/12,1)/12)))) -> 5304 | Z16: =IF($D16="",0,IF(Z$5<$N16,0,IF(Z$5<=$O16,$D16*$H16*(1+$J16)^FLOOR((Z$5-1)/12,1)/12,IF(Z$5<$T16,0,$D16*$X16*(1+$J16)^FLOOR((Z$5-$R16)/12,1)/12)))) -> 5304 | AA16: =IF($D16="",0,IF(AA$5<$N16,0,IF(AA$5<=$O16,$D16*$H16*(1+$J16)^FLOOR((AA$5-1)/12,1)/12,IF(AA$5<$T16,0,$D16*$X16*(1+$J16)^FLOOR((AA$5-$R16)/12,1)/12)))) -> 5304 | AB16: =IF($D16="",0,IF(AB$5<$N16,0,IF(AB$5<=$O16,$D16*$H16*(1+$J16)^FLOOR((AB$5-1)/12,1)/12,IF(AB$5<$T16,0,$D16*$X16*(1+$J16)^FLOOR((AB$5-$R16)/12,1)/12)))) -> 5304 | AC16: =IF($D16="",0,IF(AC$5<$N16,0,IF(AC$5<=$O16,$D16*$H16*(1+$J16)^FLOOR((AC$5-1)/12,1)/12,IF(AC$5<$T16,0,$D16*$X16*(1+$J16)^FLOOR((AC$5-$R16)/12,1)/12)))) -> 5304 | AD16: =IF($D16="",0,IF(AD$5<$N16,0,IF(AD$5<=$O16,$D16*$H16*(1+$J16)^FLOOR((AD$5-1)/12,1)/12,IF(AD$5<$T16,0,$D16*$X16*(1+$J16)^FLOOR((AD$5-$R16)/12,1)/12)))) -> 5304 | AE16: =IF($D16="",0,IF(AE$5<$N16,0,IF(AE$5<=$O16,$D16*$H16*(1+$J16)^FLOOR((AE$5-1)/12,1)/12,IF(AE$5<$T16,0,$D16*$X16*(1+$J16)^FLOOR((AE$5-$R16)/12,1)/12)))) -> 5304 | AF16: =IF($D16="",0,IF(AF$5<$N16,0,IF(AF$5<=$O16,$D16*$H16*(1+$J16)^FLOOR((AF$5-1)/12,1)/12,IF(AF$5<$T16,0,$D16*$X16*(1+$J16)^FLOOR((AF$5-$R16)/12,1)/12)))) -> 5304 | ... EN16: =IF($D16="",0,IF(EN$5<$N16,0,IF(EN$5<=$O16,$D16*$H16*(1+$J16)^FLOOR((EN$5-1)/12,1)/12,IF(EN$5<$T16,0,$D16*$X16*(1+$J16)^FLOOR((EN$5-$R16)/12,1)/12)))) -> 11315.329
B17: 226 | C17: Meyer Logistics | D17: 10800 | E17: =IFERROR(D17/TotalSF,0) -> 0.0089050132 | F17: 41671 | G17: 46296 | H17: 8.75 | I17: =IFERROR(D17*H17,0) -> 94500 | J17: 0.04 | K17: NNN | L17: 13 | M17: Renew | N17: =IF(F17="",0,(YEAR(F17)-YEAR(AnalysisStart))*12+(MONTH(F17)-MONTH(AnalysisStart))+1) -> -118 | O17: =IF(G17="",0,(YEAR(G17)-YEAR(AnalysisStart))*12+(MONTH(G17)-MONTH(AnalysisStart))+1) -> 34 | P17: =IF(D17="",0,MAX(1,O17+1)) -> 35 | Q17: =IF(D17="",0,Downtime_Ren*Retention_Ratio+Downtime_New*(1-Retention_Ratio)) -> 3 | R17: =IF(D17="",0,MIN(120,P17+Q17)) -> 38 | S17: =IF(D17="",0,FreeRent_New*(1-Retention_Ratio)+FreeRent_Ren*Retention_Ratio) -> 1 | T17: =IF(D17="",0,MIN(121,R17+S17)) -> 39 | U17: =IF(D17="",0,MIN(10,MAX(1,CEILING(R17/12,1)))) -> 4 | V17: =IF(D17="",0,(Retention_Ratio*TI_Ren+(1-Retention_Ratio)*TI_New)*D17) -> 25650 | W17: =IF(D17="",0,Retention_Ratio*LC_Ren*LeaseTermYrs*'Rent Roll'!D17*'Rent Roll'!X17+(1-Retention_Ratio)*LC_Ren*LeaseTermYrs*'Rent Roll'!D17*'Rent Roll'!X17) -> 24377.929 | X17: =IF(D17="",0,L17*INDEX(MktRentSchedule,U17)/MktRentY1) -> 15.048104 | Y17: =IF($D17="",0,IF(Y$5<$N17,0,IF(Y$5<=$O17,$D17*$H17*(1+$J17)^FLOOR((Y$5-1)/12,1)/12,IF(Y$5<$T17,0,$D17*$X17*(1+$J17)^FLOOR((Y$5-$R17)/12,1)/12)))) -> 7875 | Z17: =IF($D17="",0,IF(Z$5<$N17,0,IF(Z$5<=$O17,$D17*$H17*(1+$J17)^FLOOR((Z$5-1)/12,1)/12,IF(Z$5<$T17,0,$D17*$X17*(1+$J17)^FLOOR((Z$5-$R17)/12,1)/12)))) -> 7875 | AA17: =IF($D17="",0,IF(AA$5<$N17,0,IF(AA$5<=$O17,$D17*$H17*(1+$J17)^FLOOR((AA$5-1)/12,1)/12,IF(AA$5<$T17,0,$D17*$X17*(1+$J17)^FLOOR((AA$5-$R17)/12,1)/12)))) -> 7875 | AB17: =IF($D17="",0,IF(AB$5<$N17,0,IF(AB$5<=$O17,$D17*$H17*(1+$J17)^FLOOR((AB$5-1)/12,1)/12,IF(AB$5<$T17,0,$D17*$X17*(1+$J17)^FLOOR((AB$5-$R17)/12,1)/12)))) -> 7875 | AC17: =IF($D17="",0,IF(AC$5<$N17,0,IF(AC$5<=$O17,$D17*$H17*(1+$J17)^FLOOR((AC$5-1)/12,1)/12,IF(AC$5<$T17,0,$D17*$X17*(1+$J17)^FLOOR((AC$5-$R17)/12,1)/12)))) -> 7875 | AD17: =IF($D17="",0,IF(AD$5<$N17,0,IF(AD$5<=$O17,$D17*$H17*(1+$J17)^FLOOR((AD$5-1)/12,1)/12,IF(AD$5<$T17,0,$D17*$X17*(1+$J17)^FLOOR((AD$5-$R17)/12,1)/12)))) -> 7875 | AE17: =IF($D17="",0,IF(AE$5<$N17,0,IF(AE$5<=$O17,$D17*$H17*(1+$J17)^FLOOR((AE$5-1)/12,1)/12,IF(AE$5<$T17,0,$D17*$X17*(1+$J17)^FLOOR((AE$5-$R17)/12,1)/12)))) -> 7875 | AF17: =IF($D17="",0,IF(AF$5<$N17,0,IF(AF$5<=$O17,$D17*$H17*(1+$J17)^FLOOR((AF$5-1)/12,1)/12,IF(AF$5<$T17,0,$D17*$X17*(1+$J17)^FLOOR((AF$5-$R17)/12,1)/12)))) -> 7875 | ... EN17: =IF($D17="",0,IF(EN$5<$N17,0,IF(EN$5<=$O17,$D17*$H17*(1+$J17)^FLOOR((EN$5-1)/12,1)/12,IF(EN$5<$T17,0,$D17*$X17*(1+$J17)^FLOOR((EN$5-$R17)/12,1)/12)))) -> 17136.588
B18: 227 | C18: Sunset Marketing | D18: 10800 | E18: =IFERROR(D18/TotalSF,0) -> 0.0089050132 | F18: 37681 | G18: 45597 | H18: 8.2 | I18: =IFERROR(D18*H18,0) -> 88560 | J18: 0.03 | K18: NNN | L18: 13 | M18: Renew | N18: =IF(F18="",0,(YEAR(F18)-YEAR(AnalysisStart))*12+(MONTH(F18)-MONTH(AnalysisStart))+1) -> -249 | O18: =IF(G18="",0,(YEAR(G18)-YEAR(AnalysisStart))*12+(MONTH(G18)-MONTH(AnalysisStart))+1) -> 11 | P18: =IF(D18="",0,MAX(1,O18+1)) -> 12 | Q18: =IF(D18="",0,Downtime_Ren*Retention_Ratio+Downtime_New*(1-Retention_Ratio)) -> 3 | R18: =IF(D18="",0,MIN(120,P18+Q18)) -> 15 | S18: =IF(D18="",0,FreeRent_New*(1-Retention_Ratio)+FreeRent_Ren*Retention_Ratio) -> 1 | T18: =IF(D18="",0,MIN(121,R18+S18)) -> 16 | U18: =IF(D18="",0,MIN(10,MAX(1,CEILING(R18/12,1)))) -> 2 | V18: =IF(D18="",0,(Retention_Ratio*TI_Ren+(1-Retention_Ratio)*TI_New)*D18) -> 25650 | W18: =IF(D18="",0,Retention_Ratio*LC_Ren*LeaseTermYrs*'Rent Roll'!D18*'Rent Roll'!X18+(1-Retention_Ratio)*LC_Ren*LeaseTermYrs*'Rent Roll'!D18*'Rent Roll'!X18) -> 22323.6 | X18: =IF(D18="",0,L18*INDEX(MktRentSchedule,U18)/MktRentY1) -> 13.78 | Y18: =IF($D18="",0,IF(Y$5<$N18,0,IF(Y$5<=$O18,$D18*$H18*(1+$J18)^FLOOR((Y$5-1)/12,1)/12,IF(Y$5<$T18,0,$D18*$X18*(1+$J18)^FLOOR((Y$5-$R18)/12,1)/12)))) -> 7380 | Z18: =IF($D18="",0,IF(Z$5<$N18,0,IF(Z$5<=$O18,$D18*$H18*(1+$J18)^FLOOR((Z$5-1)/12,1)/12,IF(Z$5<$T18,0,$D18*$X18*(1+$J18)^FLOOR((Z$5-$R18)/12,1)/12)))) -> 7380 | AA18: =IF($D18="",0,IF(AA$5<$N18,0,IF(AA$5<=$O18,$D18*$H18*(1+$J18)^FLOOR((AA$5-1)/12,1)/12,IF(AA$5<$T18,0,$D18*$X18*(1+$J18)^FLOOR((AA$5-$R18)/12,1)/12)))) -> 7380 | AB18: =IF($D18="",0,IF(AB$5<$N18,0,IF(AB$5<=$O18,$D18*$H18*(1+$J18)^FLOOR((AB$5-1)/12,1)/12,IF(AB$5<$T18,0,$D18*$X18*(1+$J18)^FLOOR((AB$5-$R18)/12,1)/12)))) -> 7380 | AC18: =IF($D18="",0,IF(AC$5<$N18,0,IF(AC$5<=$O18,$D18*$H18*(1+$J18)^FLOOR((AC$5-1)/12,1)/12,IF(AC$5<$T18,0,$D18*$X18*(1+$J18)^FLOOR((AC$5-$R18)/12,1)/12)))) -> 7380 | AD18: =IF($D18="",0,IF(AD$5<$N18,0,IF(AD$5<=$O18,$D18*$H18*(1+$J18)^FLOOR((AD$5-1)/12,1)/12,IF(AD$5<$T18,0,$D18*$X18*(1+$J18)^FLOOR((AD$5-$R18)/12,1)/12)))) -> 7380 | AE18: =IF($D18="",0,IF(AE$5<$N18,0,IF(AE$5<=$O18,$D18*$H18*(1+$J18)^FLOOR((AE$5-1)/12,1)/12,IF(AE$5<$T18,0,$D18*$X18*(1+$J18)^FLOOR((AE$5-$R18)/12,1)/12)))) -> 7380 | AF18: =IF($D18="",0,IF(AF$5<$N18,0,IF(AF$5<=$O18,$D18*$H18*(1+$J18)^FLOOR((AF$5-1)/12,1)/12,IF(AF$5<$T18,0,$D18*$X18*(1+$J18)^FLOOR((AF$5-$R18)/12,1)/12)))) -> 7380 | ... EN18: =IF($D18="",0,IF(EN$5<$N18,0,IF(EN$5<=$O18,$D18*$H18*(1+$J18)^FLOOR((EN$5-1)/12,1)/12,IF(EN$5<$T18,0,$D18*$X18*(1+$J18)^FLOOR((EN$5-$R18)/12,1)/12)))) -> 15710.483
B19: 232 | C19: Uppercut Box Co. | D19: 10800 | E19: =IFERROR(D19/TotalSF,0) -> 0.0089050132 | F19: 44287 | G19: 46113 | H19: 7.96 | I19: =IFERROR(D19*H19,0) -> 85968 | J19: 0.03 | K19: NNN | L19: 13 | M19: Renew | N19: =IF(F19="",0,(YEAR(F19)-YEAR(AnalysisStart))*12+(MONTH(F19)-MONTH(AnalysisStart))+1) -> -32 | O19: =IF(G19="",0,(YEAR(G19)-YEAR(AnalysisStart))*12+(MONTH(G19)-MONTH(AnalysisStart))+1) -> 28 | P19: =IF(D19="",0,MAX(1,O19+1)) -> 29 | Q19: =IF(D19="",0,Downtime_Ren*Retention_Ratio+Downtime_New*(1-Retention_Ratio)) -> 3 | R19: =IF(D19="",0,MIN(120,P19+Q19)) -> 32 | S19: =IF(D19="",0,FreeRent_New*(1-Retention_Ratio)+FreeRent_Ren*Retention_Ratio) -> 1 | T19: =IF(D19="",0,MIN(121,R19+S19)) -> 33 | U19: =IF(D19="",0,MIN(10,MAX(1,CEILING(R19/12,1)))) -> 3 | V19: =IF(D19="",0,(Retention_Ratio*TI_Ren+(1-Retention_Ratio)*TI_New)*D19) -> 25650 | W19: =IF(D19="",0,Retention_Ratio*LC_Ren*LeaseTermYrs*'Rent Roll'!D19*'Rent Roll'!X19+(1-Retention_Ratio)*LC_Ren*LeaseTermYrs*'Rent Roll'!D19*'Rent Roll'!X19) -> 23328.162 | X19: =IF(D19="",0,L19*INDEX(MktRentSchedule,U19)/MktRentY1) -> 14.4001 | Y19: =IF($D19="",0,IF(Y$5<$N19,0,IF(Y$5<=$O19,$D19*$H19*(1+$J19)^FLOOR((Y$5-1)/12,1)/12,IF(Y$5<$T19,0,$D19*$X19*(1+$J19)^FLOOR((Y$5-$R19)/12,1)/12)))) -> 7164 | Z19: =IF($D19="",0,IF(Z$5<$N19,0,IF(Z$5<=$O19,$D19*$H19*(1+$J19)^FLOOR((Z$5-1)/12,1)/12,IF(Z$5<$T19,0,$D19*$X19*(1+$J19)^FLOOR((Z$5-$R19)/12,1)/12)))) -> 7164 | AA19: =IF($D19="",0,IF(AA$5<$N19,0,IF(AA$5<=$O19,$D19*$H19*(1+$J19)^FLOOR((AA$5-1)/12,1)/12,IF(AA$5<$T19,0,$D19*$X19*(1+$J19)^FLOOR((AA$5-$R19)/12,1)/12)))) -> 7164 | AB19: =IF($D19="",0,IF(AB$5<$N19,0,IF(AB$5<=$O19,$D19*$H19*(1+$J19)^FLOOR((AB$5-1)/12,1)/12,IF(AB$5<$T19,0,$D19*$X19*(1+$J19)^FLOOR((AB$5-$R19)/12,1)/12)))) -> 7164 | AC19: =IF($D19="",0,IF(AC$5<$N19,0,IF(AC$5<=$O19,$D19*$H19*(1+$J19)^FLOOR((AC$5-1)/12,1)/12,IF(AC$5<$T19,0,$D19*$X19*(1+$J19)^FLOOR((AC$5-$R19)/12,1)/12)))) -> 7164 | AD19: =IF($D19="",0,IF(AD$5<$N19,0,IF(AD$5<=$O19,$D19*$H19*(1+$J19)^FLOOR((AD$5-1)/12,1)/12,IF(AD$5<$T19,0,$D19*$X19*(1+$J19)^FLOOR((AD$5-$R19)/12,1)/12)))) -> 7164 | AE19: =IF($D19="",0,IF(AE$5<$N19,0,IF(AE$5<=$O19,$D19*$H19*(1+$J19)^FLOOR((AE$5-1)/12,1)/12,IF(AE$5<$T19,0,$D19*$X19*(1+$J19)^FLOOR((AE$5-$R19)/12,1)/12)))) -> 7164 | AF19: =IF($D19="",0,IF(AF$5<$N19,0,IF(AF$5<=$O19,$D19*$H19*(1+$J19)^FLOOR((AF$5-1)/12,1)/12,IF(AF$5<$T19,0,$D19*$X19*(1+$J19)^FLOOR((AF$5-$R19)/12,1)/12)))) -> 7164 | ... EN19: =IF($D19="",0,IF(EN$5<$N19,0,IF(EN$5<=$O19,$D19*$H19*(1+$J19)^FLOOR((EN$5-1)/12,1)/12,IF(EN$5<$T19,0,$D19*$X19*(1+$J19)^FLOOR((EN$5-$R19)/12,1)/12)))) -> 15939.276
B20: 235 | C20: Surtidora El Mana | D20: 10800 | E20: =IFERROR(D20/TotalSF,0) -> 0.0089050132 | F20: 44409 | G20: 46569 | H20: 9.51 | I20: =IFERROR(D20*H20,0) -> 102708 | J20: 0.04 | K20: NNN | L20: 13 | M20: Renew | N20: =IF(F20="",0,(YEAR(F20)-YEAR(AnalysisStart))*12+(MONTH(F20)-MONTH(AnalysisStart))+1) -> -28 | O20: =IF(G20="",0,(YEAR(G20)-YEAR(AnalysisStart))*12+(MONTH(G20)-MONTH(AnalysisStart))+1) -> 43 | P20: =IF(D20="",0,MAX(1,O20+1)) -> 44 | Q20: =IF(D20="",0,Downtime_Ren*Retention_Ratio+Downtime_New*(1-Retention_Ratio)) -> 3 | R20: =IF(D20="",0,MIN(120,P20+Q20)) -> 47 | S20: =IF(D20="",0,FreeRent_New*(1-Retention_Ratio)+FreeRent_Ren*Retention_Ratio) -> 1 | T20: =IF(D20="",0,MIN(121,R20+S20)) -> 48 | U20: =IF(D20="",0,MIN(10,MAX(1,CEILING(R20/12,1)))) -> 4 | V20: =IF(D20="",0,(Retention_Ratio*TI_Ren+(1-Retention_Ratio)*TI_New)*D20) -> 25650 | W20: =IF(D20="",0,Retention_Ratio*LC_Ren*LeaseTermYrs*'Rent Roll'!D20*'Rent Roll'!X20+(1-Retention_Ratio)*LC_Ren*LeaseTermYrs*'Rent Roll'!D20*'Rent Roll'!X20) -> 24377.929 | X20: =IF(D20="",0,L20*INDEX(MktRentSchedule,U20)/MktRentY1) -> 15.048104 | Y20: =IF($D20="",0,IF(Y$5<$N20,0,IF(Y$5<=$O20,$D20*$H20*(1+$J20)^FLOOR((Y$5-1)/12,1)/12,IF(Y$5<$T20,0,$D20*$X20*(1+$J20)^FLOOR((Y$5-$R20)/12,1)/12)))) -> 8559 | Z20: =IF($D20="",0,IF(Z$5<$N20,0,IF(Z$5<=$O20,$D20*$H20*(1+$J20)^FLOOR((Z$5-1)/12,1)/12,IF(Z$5<$T20,0,$D20*$X20*(1+$J20)^FLOOR((Z$5-$R20)/12,1)/12)))) -> 8559 | AA20: =IF($D20="",0,IF(AA$5<$N20,0,IF(AA$5<=$O20,$D20*$H20*(1+$J20)^FLOOR((AA$5-1)/12,1)/12,IF(AA$5<$T20,0,$D20*$X20*(1+$J20)^FLOOR((AA$5-$R20)/12,1)/12)))) -> 8559 | AB20: =IF($D20="",0,IF(AB$5<$N20,0,IF(AB$5<=$O20,$D20*$H20*(1+$J20)^FLOOR((AB$5-1)/12,1)/12,IF(AB$5<$T20,0,$D20*$X20*(1+$J20)^FLOOR((AB$5-$R20)/12,1)/12)))) -> 8559 | AC20: =IF($D20="",0,IF(AC$5<$N20,0,IF(AC$5<=$O20,$D20*$H20*(1+$J20)^FLOOR((AC$5-1)/12,1)/12,IF(AC$5<$T20,0,$D20*$X20*(1+$J20)^FLOOR((AC$5-$R20)/12,1)/12)))) -> 8559 | AD20: =IF($D20="",0,IF(AD$5<$N20,0,IF(AD$5<=$O20,$D20*$H20*(1+$J20)^FLOOR((AD$5-1)/12,1)/12,IF(AD$5<$T20,0,$D20*$X20*(1+$J20)^FLOOR((AD$5-$R20)/12,1)/12)))) -> 8559 | AE20: =IF($D20="",0,IF(AE$5<$N20,0,IF(AE$5<=$O20,$D20*$H20*(1+$J20)^FLOOR((AE$5-1)/12,1)/12,IF(AE$5<$T20,0,$D20*$X20*(1+$J20)^FLOOR((AE$5-$R20)/12,1)/12)))) -> 8559 | AF20: =IF($D20="",0,IF(AF$5<$N20,0,IF(AF$5<=$O20,$D20*$H20*(1+$J20)^FLOOR((AF$5-1)/12,1)/12,IF(AF$5<$T20,0,$D20*$X20*(1+$J20)^FLOOR((AF$5-$R20)/12,1)/12)))) -> 8559 | ... EN20: =IF($D20="",0,IF(EN$5<$N20,0,IF(EN$5<=$O20,$D20*$H20*(1+$J20)^FLOOR((EN$5-1)/12,1)/12,IF(EN$5<$T20,0,$D20*$X20*(1+$J20)^FLOOR((EN$5-$R20)/12,1)/12)))) -> 17136.588
B21: 236 | C21: D2D Distro | D21: 10800 | E21: =IFERROR(D21/TotalSF,0) -> 0.0089050132 | F21: 44621 | G21: 46478 | H21: 8.75 | I21: =IFERROR(D21*H21,0) -> 94500 | J21: 0.04 | K21: NNN | L21: 13 | M21: Renew | N21: =IF(F21="",0,(YEAR(F21)-YEAR(AnalysisStart))*12+(MONTH(F21)-MONTH(AnalysisStart))+1) -> -21 | O21: =IF(G21="",0,(YEAR(G21)-YEAR(AnalysisStart))*12+(MONTH(G21)-MONTH(AnalysisStart))+1) -> 40 | P21: =IF(D21="",0,MAX(1,O21+1)) -> 41 | Q21: =IF(D21="",0,Downtime_Ren*Retention_Ratio+Downtime_New*(1-Retention_Ratio)) -> 3 | R21: =IF(D21="",0,MIN(120,P21+Q21)) -> 44 | S21: =IF(D21="",0,FreeRent_New*(1-Retention_Ratio)+FreeRent_Ren*Retention_Ratio) -> 1 | T21: =IF(D21="",0,MIN(121,R21+S21)) -> 45 | U21: =IF(D21="",0,MIN(10,MAX(1,CEILING(R21/12,1)))) -> 4 | V21: =IF(D21="",0,(Retention_Ratio*TI_Ren+(1-Retention_Ratio)*TI_New)*D21) -> 25650 | W21: =IF(D21="",0,Retention_Ratio*LC_Ren*LeaseTermYrs*'Rent Roll'!D21*'Rent Roll'!X21+(1-Retention_Ratio)*LC_Ren*LeaseTermYrs*'Rent Roll'!D21*'Rent Roll'!X21) -> 24377.929 | X21: =IF(D21="",0,L21*INDEX(MktRentSchedule,U21)/MktRentY1) -> 15.048104 | Y21: =IF($D21="",0,IF(Y$5<$N21,0,IF(Y$5<=$O21,$D21*$H21*(1+$J21)^FLOOR((Y$5-1)/12,1)/12,IF(Y$5<$T21,0,$D21*$X21*(1+$J21)^FLOOR((Y$5-$R21)/12,1)/12)))) -> 7875 | Z21: =IF($D21="",0,IF(Z$5<$N21,0,IF(Z$5<=$O21,$D21*$H21*(1+$J21)^FLOOR((Z$5-1)/12,1)/12,IF(Z$5<$T21,0,$D21*$X21*(1+$J21)^FLOOR((Z$5-$R21)/12,1)/12)))) -> 7875 | AA21: =IF($D21="",0,IF(AA$5<$N21,0,IF(AA$5<=$O21,$D21*$H21*(1+$J21)^FLOOR((AA$5-1)/12,1)/12,IF(AA$5<$T21,0,$D21*$X21*(1+$J21)^FLOOR((AA$5-$R21)/12,1)/12)))) -> 7875 | AB21: =IF($D21="",0,IF(AB$5<$N21,0,IF(AB$5<=$O21,$D21*$H21*(1+$J21)^FLOOR((AB$5-1)/12,1)/12,IF(AB$5<$T21,0,$D21*$X21*(1+$J21)^FLOOR((AB$5-$R21)/12,1)/12)))) -> 7875 | AC21: =IF($D21="",0,IF(AC$5<$N21,0,IF(AC$5<=$O21,$D21*$H21*(1+$J21)^FLOOR((AC$5-1)/12,1)/12,IF(AC$5<$T21,0,$D21*$X21*(1+$J21)^FLOOR((AC$5-$R21)/12,1)/12)))) -> 7875 | AD21: =IF($D21="",0,IF(AD$5<$N21,0,IF(AD$5<=$O21,$D21*$H21*(1+$J21)^FLOOR((AD$5-1)/12,1)/12,IF(AD$5<$T21,0,$D21*$X21*(1+$J21)^FLOOR((AD$5-$R21)/12,1)/12)))) -> 7875 | AE21: =IF($D21="",0,IF(AE$5<$N21,0,IF(AE$5<=$O21,$D21*$H21*(1+$J21)^FLOOR((AE$5-1)/12,1)/12,IF(AE$5<$T21,0,$D21*$X21*(1+$J21)^FLOOR((AE$5-$R21)/12,1)/12)))) -> 7875 | AF21: =IF($D21="",0,IF(AF$5<$N21,0,IF(AF$5<=$O21,$D21*$H21*(1+$J21)^FLOOR((AF$5-1)/12,1)/12,IF(AF$5<$T21,0,$D21*$X21*(1+$J21)^FLOOR((AF$5-$R21)/12,1)/12)))) -> 7875 | ... EN21: =IF($D21="",0,IF(EN$5<$N21,0,IF(EN$5<=$O21,$D21*$H21*(1+$J21)^FLOOR((EN$5-1)/12,1)/12,IF(EN$5<$T21,0,$D21*$X21*(1+$J21)^FLOOR((EN$5-$R21)/12,1)/12)))) -> 17136.588
... B46: 1016 | C46: CAM International | D46: 95000 | E46: =IFERROR(D46/TotalSF,0) -> 0.078331135 | F46: 41640 | G46: 45352 | H46: 3.88 | I46: =IFERROR(D46*H46,0) -> 368600 | J46: 0 | K46: NNN | L46: 8 | M46: Vacate | N46: =IF(F46="",0,(YEAR(F46)-YEAR(AnalysisStart))*12+(MONTH(F46)-MONTH(AnalysisStart))+1) -> -119 | O46: =IF(G46="",0,(YEAR(G46)-YEAR(AnalysisStart))*12+(MONTH(G46)-MONTH(AnalysisStart))+1) -> 3 | P46: =IF(D46="",0,MAX(1,O46+1)) -> 4 | Q46: =IF(D46="",0,Downtime_Ren*Retention_Ratio+Downtime_New*(1-Retention_Ratio)) -> 3 | R46: =IF(D46="",0,MIN(120,P46+Q46)) -> 7 | S46: =IF(D46="",0,FreeRent_New*(1-Retention_Ratio)+FreeRent_Ren*Retention_Ratio) -> 1 | T46: =IF(D46="",0,MIN(121,R46+S46)) -> 8 | U46: =IF(D46="",0,MIN(10,MAX(1,CEILING(R46/12,1)))) -> 1 | V46: =IF(D46="",0,(Retention_Ratio*TI_Ren+(1-Retention_Ratio)*TI_New)*D46) -> 225625 | W46: =IF(D46="",0,Retention_Ratio*LC_Ren*LeaseTermYrs*'Rent Roll'!D46*'Rent Roll'!X46+(1-Retention_Ratio)*LC_Ren*LeaseTermYrs*'Rent Roll'!D46*'Rent Roll'!X46) -> 114000 | X46: =IF(D46="",0,L46*INDEX(MktRentSchedule,U46)/MktRentY1) -> 8 | Y46: =IF($D46="",0,IF(Y$5<$N46,0,IF(Y$5<=$O46,$D46*$H46*(1+$J46)^FLOOR((Y$5-1)/12,1)/12,IF(Y$5<$T46,0,$D46*$X46*(1+$J46)^FLOOR((Y$5-$R46)/12,1)/12)))) -> 30716.667 | Z46: =IF($D46="",0,IF(Z$5<$N46,0,IF(Z$5<=$O46,$D46*$H46*(1+$J46)^FLOOR((Z$5-1)/12,1)/12,IF(Z$5<$T46,0,$D46*$X46*(1+$J46)^FLOOR((Z$5-$R46)/12,1)/12)))) -> 30716.667 | AA46: =IF($D46="",0,IF(AA$5<$N46,0,IF(AA$5<=$O46,$D46*$H46*(1+$J46)^FLOOR((AA$5-1)/12,1)/12,IF(AA$5<$T46,0,$D46*$X46*(1+$J46)^FLOOR((AA$5-$R46)/12,1)/12)))) -> 30716.667 | AB46: =IF($D46="",0,IF(AB$5<$N46,0,IF(AB$5<=$O46,$D46*$H46*(1+$J46)^FLOOR((AB$5-1)/12,1)/12,IF(AB$5<$T46,0,$D46*$X46*(1+$J46)^FLOOR((AB$5-$R46)/12,1)/12)))) -> 0 | AC46: =IF($D46="",0,IF(AC$5<$N46,0,IF(AC$5<=$O46,$D46*$H46*(1+$J46)^FLOOR((AC$5-1)/12,1)/12,IF(AC$5<$T46,0,$D46*$X46*(1+$J46)^FLOOR((AC$5-$R46)/12,1)/12)))) -> 0 | AD46: =IF($D46="",0,IF(AD$5<$N46,0,IF(AD$5<=$O46,$D46*$H46*(1+$J46)^FLOOR((AD$5-1)/12,1)/12,IF(AD$5<$T46,0,$D46*$X46*(1+$J46)^FLOOR((AD$5-$R46)/12,1)/12)))) -> 0 | AE46: =IF($D46="",0,IF(AE$5<$N46,0,IF(AE$5<=$O46,$D46*$H46*(1+$J46)^FLOOR((AE$5-1)/12,1)/12,IF(AE$5<$T46,0,$D46*$X46*(1+$J46)^FLOOR((AE$5-$R46)/12,1)/12)))) -> 0 | AF46: =IF($D46="",0,IF(AF$5<$N46,0,IF(AF$5<=$O46,$D46*$H46*(1+$J46)^FLOOR((AF$5-1)/12,1)/12,IF(AF$5<$T46,0,$D46*$X46*(1+$J46)^FLOOR((AF$5-$R46)/12,1)/12)))) -> 63333.333 | ... EN46: =IF($D46="",0,IF(EN$5<$N46,0,IF(EN$5<=$O46,$D46*$H46*(1+$J46)^FLOOR((EN$5-1)/12,1)/12,IF(EN$5<$T46,0,$D46*$X46*(1+$J46)^FLOOR((EN$5-$R46)/12,1)/12)))) -> 63333.333
E47: =IFERROR(D47/TotalSF,0) -> 0 | I47: =IFERROR(D47*H47,0) -> 0 | N47: =IF(F47="",0,(YEAR(F47)-YEAR(AnalysisStart))*12+(MONTH(F47)-MONTH(AnalysisStart))+1) -> 0 | O47: =IF(G47="",0,(YEAR(G47)-YEAR(AnalysisStart))*12+(MONTH(G47)-MONTH(AnalysisStart))+1) -> 0 | P47: =IF(D47="",0,MAX(1,O47+1)) -> 0 | Q47: =IF(D47="",0,Downtime_Ren*Retention_Ratio+Downtime_New*(1-Retention_Ratio)) -> 0 | R47: =IF(D47="",0,MIN(120,P47+Q47)) -> 0 | S47: =IF(D47="",0,FreeRent_New*(1-Retention_Ratio)+FreeRent_Ren*Retention_Ratio) -> 0 | T47: =IF(D47="",0,MIN(121,R47+S47)) -> 0 | U47: =IF(D47="",0,MIN(10,MAX(1,CEILING(R47/12,1)))) -> 0 | V47: =IF(D47="",0,(Retention_Ratio*TI_Ren+(1-Retention_Ratio)*TI_New)*D47) -> 0 | W47: =IF(D47="",0,Retention_Ratio*LC_Ren*LeaseTermYrs*'Rent Roll'!D47*'Rent Roll'!X47+(1-Retention_Ratio)*LC_Ren*LeaseTermYrs*'Rent Roll'!D47*'Rent Roll'!X47) -> 0 | X47: =IF(D47="",0,L47*INDEX(MktRentSchedule,U47)/MktRentY1) -> 0 | Y47: =IF($D47="",0,IF(Y$5<$N47,0,IF(Y$5<=$O47,$D47*$H47*(1+$J47)^FLOOR((Y$5-1)/12,1)/12,IF(Y$5<$T47,0,$D47*$X47*(1+$J47)^FLOOR((Y$5-$R47)/12,1)/12)))) -> 0 | Z47: =IF($D47="",0,IF(Z$5<$N47,0,IF(Z$5<=$O47,$D47*$H47*(1+$J47)^FLOOR((Z$5-1)/12,1)/12,IF(Z$5<$T47,0,$D47*$X47*(1+$J47)^FLOOR((Z$5-$R47)/12,1)/12)))) -> 0 | AA47: =IF($D47="",0,IF(AA$5<$N47,0,IF(AA$5<=$O47,$D47*$H47*(1+$J47)^FLOOR((AA$5-1)/12,1)/12,IF(AA$5<$T47,0,$D47*$X47*(1+$J47)^FLOOR((AA$5-$R47)/12,1)/12)))) -> 0 | AB47: =IF($D47="",0,IF(AB$5<$N47,0,IF(AB$5<=$O47,$D47*$H47*(1+$J47)^FLOOR((AB$5-1)/12,1)/12,IF(AB$5<$T47,0,$D47*$X47*(1+$J47)^FLOOR((AB$5-$R47)/12,1)/12)))) -> 0 | AC47: =IF($D47="",0,IF(AC$5<$N47,0,IF(AC$5<=$O47,$D47*$H47*(1+$J47)^FLOOR((AC$5-1)/12,1)/12,IF(AC$5<$T47,0,$D47*$X47*(1+$J47)^FLOOR((AC$5-$R47)/12,1)/12)))) -> 0 | AD47: =IF($D47="",0,IF(AD$5<$N47,0,IF(AD$5<=$O47,$D47*$H47*(1+$J47)^FLOOR((AD$5-1)/12,1)/12,IF(AD$5<$T47,0,$D47*$X47*(1+$J47)^FLOOR((AD$5-$R47)/12,1)/12)))) -> 0 | AE47: =IF($D47="",0,IF(AE$5<$N47,0,IF(AE$5<=$O47,$D47*$H47*(1+$J47)^FLOOR((AE$5-1)/12,1)/12,IF(AE$5<$T47,0,$D47*$X47*(1+$J47)^FLOOR((AE$5-$R47)/12,1)/12)))) -> 0 | AF47: =IF($D47="",0,IF(AF$5<$N47,0,IF(AF$5<=$O47,$D47*$H47*(1+$J47)^FLOOR((AF$5-1)/12,1)/12,IF(AF$5<$T47,0,$D47*$X47*(1+$J47)^FLOOR((AF$5-$R47)/12,1)/12)))) -> 0 | ... EN47: =IF($D47="",0,IF(EN$5<$N47,0,IF(EN$5<=$O47,$D47*$H47*(1+$J47)^FLOOR((EN$5-1)/12,1)/12,IF(EN$5<$T47,0,$D47*$X47*(1+$J47)^FLOOR((EN$5-$R47)/12,1)/12)))) -> 0
E48: =IFERROR(D48/TotalSF,0) -> 0 | I48: =IFERROR(D48*H48,0) -> 0 | N48: =IF(F48="",0,(YEAR(F48)-YEAR(AnalysisStart))*12+(MONTH(F48)-MONTH(AnalysisStart))+1) -> 0 | O48: =IF(G48="",0,(YEAR(G48)-YEAR(AnalysisStart))*12+(MONTH(G48)-MONTH(AnalysisStart))+1) -> 0 | P48: =IF(D48="",0,MAX(1,O48+1)) -> 0 | Q48: =IF(D48="",0,Downtime_Ren*Retention_Ratio+Downtime_New*(1-Retention_Ratio)) -> 0 | R48: =IF(D48="",0,MIN(120,P48+Q48)) -> 0 | S48: =IF(D48="",0,FreeRent_New*(1-Retention_Ratio)+FreeRent_Ren*Retention_Ratio) -> 0 | T48: =IF(D48="",0,MIN(121,R48+S48)) -> 0 | U48: =IF(D48="",0,MIN(10,MAX(1,CEILING(R48/12,1)))) -> 0 | V48: =IF(D48="",0,(Retention_Ratio*TI_Ren+(1-Retention_Ratio)*TI_New)*D48) -> 0 | W48: =IF(D48="",0,Retention_Ratio*LC_Ren*LeaseTermYrs*'Rent Roll'!D48*'Rent Roll'!X48+(1-Retention_Ratio)*LC_Ren*LeaseTermYrs*'Rent Roll'!D48*'Rent Roll'!X48) -> 0 | X48: =IF(D48="",0,L48*INDEX(MktRentSchedule,U48)/MktRentY1) -> 0 | Y48: =IF($D48="",0,IF(Y$5<$N48,0,IF(Y$5<=$O48,$D48*$H48*(1+$J48)^FLOOR((Y$5-1)/12,1)/12,IF(Y$5<$T48,0,$D48*$X48*(1+$J48)^FLOOR((Y$5-$R48)/12,1)/12)))) -> 0 | Z48: =IF($D48="",0,IF(Z$5<$N48,0,IF(Z$5<=$O48,$D48*$H48*(1+$J48)^FLOOR((Z$5-1)/12,1)/12,IF(Z$5<$T48,0,$D48*$X48*(1+$J48)^FLOOR((Z$5-$R48)/12,1)/12)))) -> 0 | AA48: =IF($D48="",0,IF(AA$5<$N48,0,IF(AA$5<=$O48,$D48*$H48*(1+$J48)^FLOOR((AA$5-1)/12,1)/12,IF(AA$5<$T48,0,$D48*$X48*(1+$J48)^FLOOR((AA$5-$R48)/12,1)/12)))) -> 0 | AB48: =IF($D48="",0,IF(AB$5<$N48,0,IF(AB$5<=$O48,$D48*$H48*(1+$J48)^FLOOR((AB$5-1)/12,1)/12,IF(AB$5<$T48,0,$D48*$X48*(1+$J48)^FLOOR((AB$5-$R48)/12,1)/12)))) -> 0 | AC48: =IF($D48="",0,IF(AC$5<$N48,0,IF(AC$5<=$O48,$D48*$H48*(1+$J48)^FLOOR((AC$5-1)/12,1)/12,IF(AC$5<$T48,0,$D48*$X48*(1+$J48)^FLOOR((AC$5-$R48)/12,1)/12)))) -> 0 | AD48: =IF($D48="",0,IF(AD$5<$N48,0,IF(AD$5<=$O48,$D48*$H48*(1+$J48)^FLOOR((AD$5-1)/12,1)/12,IF(AD$5<$T48,0,$D48*$X48*(1+$J48)^FLOOR((AD$5-$R48)/12,1)/12)))) -> 0 | AE48: =IF($D48="",0,IF(AE$5<$N48,0,IF(AE$5<=$O48,$D48*$H48*(1+$J48)^FLOOR((AE$5-1)/12,1)/12,IF(AE$5<$T48,0,$D48*$X48*(1+$J48)^FLOOR((AE$5-$R48)/12,1)/12)))) -> 0 | AF48: =IF($D48="",0,IF(AF$5<$N48,0,IF(AF$5<=$O48,$D48*$H48*(1+$J48)^FLOOR((AF$5-1)/12,1)/12,IF(AF$5<$T48,0,$D48*$X48*(1+$J48)^FLOOR((AF$5-$R48)/12,1)/12)))) -> 0 | ... EN48: =IF($D48="",0,IF(EN$5<$N48,0,IF(EN$5<=$O48,$D48*$H48*(1+$J48)^FLOOR((EN$5-1)/12,1)/12,IF(EN$5<$T48,0,$D48*$X48*(1+$J48)^FLOOR((EN$5-$R48)/12,1)/12)))) -> 0
E49: =IFERROR(D49/TotalSF,0) -> 0 | I49: =IFERROR(D49*H49,0) -> 0 | N49: =IF(F49="",0,(YEAR(F49)-YEAR(AnalysisStart))*12+(MONTH(F49)-MONTH(AnalysisStart))+1) -> 0 | O49: =IF(G49="",0,(YEAR(G49)-YEAR(AnalysisStart))*12+(MONTH(G49)-MONTH(AnalysisStart))+1) -> 0 | P49: =IF(D49="",0,MAX(1,O49+1)) -> 0 | Q49: =IF(D49="",0,Downtime_Ren*Retention_Ratio+Downtime_New*(1-Retention_Ratio)) -> 0 | R49: =IF(D49="",0,MIN(120,P49+Q49)) -> 0 | S49: =IF(D49="",0,FreeRent_New*(1-Retention_Ratio)+FreeRent_Ren*Retention_Ratio) -> 0 | T49: =IF(D49="",0,MIN(121,R49+S49)) -> 0 | U49: =IF(D49="",0,MIN(10,MAX(1,CEILING(R49/12,1)))) -> 0 | V49: =IF(D49="",0,(Retention_Ratio*TI_Ren+(1-Retention_Ratio)*TI_New)*D49) -> 0 | W49: =IF(D49="",0,Retention_Ratio*LC_Ren*LeaseTermYrs*'Rent Roll'!D49*'Rent Roll'!X49+(1-Retention_Ratio)*LC_Ren*LeaseTermYrs*'Rent Roll'!D49*'Rent Roll'!X49) -> 0 | X49: =IF(D49="",0,L49*INDEX(MktRentSchedule,U49)/MktRentY1) -> 0 | Y49: =IF($D49="",0,IF(Y$5<$N49,0,IF(Y$5<=$O49,$D49*$H49*(1+$J49)^FLOOR((Y$5-1)/12,1)/12,IF(Y$5<$T49,0,$D49*$X49*(1+$J49)^FLOOR((Y$5-$R49)/12,1)/12)))) -> 0 | Z49: =IF($D49="",0,IF(Z$5<$N49,0,IF(Z$5<=$O49,$D49*$H49*(1+$J49)^FLOOR((Z$5-1)/12,1)/12,IF(Z$5<$T49,0,$D49*$X49*(1+$J49)^FLOOR((Z$5-$R49)/12,1)/12)))) -> 0 | AA49: =IF($D49="",0,IF(AA$5<$N49,0,IF(AA$5<=$O49,$D49*$H49*(1+$J49)^FLOOR((AA$5-1)/12,1)/12,IF(AA$5<$T49,0,$D49*$X49*(1+$J49)^FLOOR((AA$5-$R49)/12,1)/12)))) -> 0 | AB49: =IF($D49="",0,IF(AB$5<$N49,0,IF(AB$5<=$O49,$D49*$H49*(1+$J49)^FLOOR((AB$5-1)/12,1)/12,IF(AB$5<$T49,0,$D49*$X49*(1+$J49)^FLOOR((AB$5-$R49)/12,1)/12)))) -> 0 | AC49: =IF($D49="",0,IF(AC$5<$N49,0,IF(AC$5<=$O49,$D49*$H49*(1+$J49)^FLOOR((AC$5-1)/12,1)/12,IF(AC$5<$T49,0,$D49*$X49*(1+$J49)^FLOOR((AC$5-$R49)/12,1)/12)))) -> 0 | AD49: =IF($D49="",0,IF(AD$5<$N49,0,IF(AD$5<=$O49,$D49*$H49*(1+$J49)^FLOOR((AD$5-1)/12,1)/12,IF(AD$5<$T49,0,$D49*$X49*(1+$J49)^FLOOR((AD$5-$R49)/12,1)/12)))) -> 0 | AE49: =IF($D49="",0,IF(AE$5<$N49,0,IF(AE$5<=$O49,$D49*$H49*(1+$J49)^FLOOR((AE$5-1)/12,1)/12,IF(AE$5<$T49,0,$D49*$X49*(1+$J49)^FLOOR((AE$5-$R49)/12,1)/12)))) -> 0 | AF49: =IF($D49="",0,IF(AF$5<$N49,0,IF(AF$5<=$O49,$D49*$H49*(1+$J49)^FLOOR((AF$5-1)/12,1)/12,IF(AF$5<$T49,0,$D49*$X49*(1+$J49)^FLOOR((AF$5-$R49)/12,1)/12)))) -> 0 | ... EN49: =IF($D49="",0,IF(EN$5<$N49,0,IF(EN$5<=$O49,$D49*$H49*(1+$J49)^FLOOR((EN$5-1)/12,1)/12,IF(EN$5<$T49,0,$D49*$X49*(1+$J49)^FLOOR((EN$5-$R49)/12,1)/12)))) -> 0
E50: =IFERROR(D50/TotalSF,0) -> 0 | I50: =IFERROR(D50*H50,0) -> 0 | N50: =IF(F50="",0,(YEAR(F50)-YEAR(AnalysisStart))*12+(MONTH(F50)-MONTH(AnalysisStart))+1) -> 0 | O50: =IF(G50="",0,(YEAR(G50)-YEAR(AnalysisStart))*12+(MONTH(G50)-MONTH(AnalysisStart))+1) -> 0 | P50: =IF(D50="",0,MAX(1,O50+1)) -> 0 | Q50: =IF(D50="",0,Downtime_Ren*Retention_Ratio+Downtime_New*(1-Retention_Ratio)) -> 0 | R50: =IF(D50="",0,MIN(120,P50+Q50)) -> 0 | S50: =IF(D50="",0,FreeRent_New*(1-Retention_Ratio)+FreeRent_Ren*Retention_Ratio) -> 0 | T50: =IF(D50="",0,MIN(121,R50+S50)) -> 0 | U50: =IF(D50="",0,MIN(10,MAX(1,CEILING(R50/12,1)))) -> 0 | V50: =IF(D50="",0,(Retention_Ratio*TI_Ren+(1-Retention_Ratio)*TI_New)*D50) -> 0 | W50: =IF(D50="",0,Retention_Ratio*LC_Ren*LeaseTermYrs*'Rent Roll'!D50*'Rent Roll'!X50+(1-Retention_Ratio)*LC_Ren*LeaseTermYrs*'Rent Roll'!D50*'Rent Roll'!X50) -> 0 | X50: =IF(D50="",0,L50*INDEX(MktRentSchedule,U50)/MktRentY1) -> 0 | Y50: =IF($D50="",0,IF(Y$5<$N50,0,IF(Y$5<=$O50,$D50*$H50*(1+$J50)^FLOOR((Y$5-1)/12,1)/12,IF(Y$5<$T50,0,$D50*$X50*(1+$J50)^FLOOR((Y$5-$R50)/12,1)/12)))) -> 0 | Z50: =IF($D50="",0,IF(Z$5<$N50,0,IF(Z$5<=$O50,$D50*$H50*(1+$J50)^FLOOR((Z$5-1)/12,1)/12,IF(Z$5<$T50,0,$D50*$X50*(1+$J50)^FLOOR((Z$5-$R50)/12,1)/12)))) -> 0 | AA50: =IF($D50="",0,IF(AA$5<$N50,0,IF(AA$5<=$O50,$D50*$H50*(1+$J50)^FLOOR((AA$5-1)/12,1)/12,IF(AA$5<$T50,0,$D50*$X50*(1+$J50)^FLOOR((AA$5-$R50)/12,1)/12)))) -> 0 | AB50: =IF($D50="",0,IF(AB$5<$N50,0,IF(AB$5<=$O50,$D50*$H50*(1+$J50)^FLOOR((AB$5-1)/12,1)/12,IF(AB$5<$T50,0,$D50*$X50*(1+$J50)^FLOOR((AB$5-$R50)/12,1)/12)))) -> 0 | AC50: =IF($D50="",0,IF(AC$5<$N50,0,IF(AC$5<=$O50,$D50*$H50*(1+$J50)^FLOOR((AC$5-1)/12,1)/12,IF(AC$5<$T50,0,$D50*$X50*(1+$J50)^FLOOR((AC$5-$R50)/12,1)/12)))) -> 0 | AD50: =IF($D50="",0,IF(AD$5<$N50,0,IF(AD$5<=$O50,$D50*$H50*(1+$J50)^FLOOR((AD$5-1)/12,1)/12,IF(AD$5<$T50,0,$D50*$X50*(1+$J50)^FLOOR((AD$5-$R50)/12,1)/12)))) -> 0 | AE50: =IF($D50="",0,IF(AE$5<$N50,0,IF(AE$5<=$O50,$D50*$H50*(1+$J50)^FLOOR((AE$5-1)/12,1)/12,IF(AE$5<$T50,0,$D50*$X50*(1+$J50)^FLOOR((AE$5-$R50)/12,1)/12)))) -> 0 | AF50: =IF($D50="",0,IF(AF$5<$N50,0,IF(AF$5<=$O50,$D50*$H50*(1+$J50)^FLOOR((AF$5-1)/12,1)/12,IF(AF$5<$T50,0,$D50*$X50*(1+$J50)^FLOOR((AF$5-$R50)/12,1)/12)))) -> 0 | ... EN50: =IF($D50="",0,IF(EN$5<$N50,0,IF(EN$5<=$O50,$D50*$H50*(1+$J50)^FLOOR((EN$5-1)/12,1)/12,IF(EN$5<$T50,0,$D50*$X50*(1+$J50)^FLOOR((EN$5-$R50)/12,1)/12)))) -> 0
E51: =IFERROR(D51/TotalSF,0) -> 0 | I51: =IFERROR(D51*H51,0) -> 0 | N51: =IF(F51="",0,(YEAR(F51)-YEAR(AnalysisStart))*12+(MONTH(F51)-MONTH(AnalysisStart))+1) -> 0 | O51: =IF(G51="",0,(YEAR(G51)-YEAR(AnalysisStart))*12+(MONTH(G51)-MONTH(AnalysisStart))+1) -> 0 | P51: =IF(D51="",0,MAX(1,O51+1)) -> 0 | Q51: =IF(D51="",0,Downtime_Ren*Retention_Ratio+Downtime_New*(1-Retention_Ratio)) -> 0 | R51: =IF(D51="",0,MIN(120,P51+Q51)) -> 0 | S51: =IF(D51="",0,FreeRent_New*(1-Retention_Ratio)+FreeRent_Ren*Retention_Ratio) -> 0 | T51: =IF(D51="",0,MIN(121,R51+S51)) -> 0 | U51: =IF(D51="",0,MIN(10,MAX(1,CEILING(R51/12,1)))) -> 0 | V51: =IF(D51="",0,(Retention_Ratio*TI_Ren+(1-Retention_Ratio)*TI_New)*D51) -> 0 | W51: =IF(D51="",0,Retention_Ratio*LC_Ren*LeaseTermYrs*'Rent Roll'!D51*'Rent Roll'!X51+(1-Retention_Ratio)*LC_Ren*LeaseTermYrs*'Rent Roll'!D51*'Rent Roll'!X51) -> 0 | X51: =IF(D51="",0,L51*INDEX(MktRentSchedule,U51)/MktRentY1) -> 0 | Y51: =IF($D51="",0,IF(Y$5<$N51,0,IF(Y$5<=$O51,$D51*$H51*(1+$J51)^FLOOR((Y$5-1)/12,1)/12,IF(Y$5<$T51,0,$D51*$X51*(1+$J51)^FLOOR((Y$5-$R51)/12,1)/12)))) -> 0 | Z51: =IF($D51="",0,IF(Z$5<$N51,0,IF(Z$5<=$O51,$D51*$H51*(1+$J51)^FLOOR((Z$5-1)/12,1)/12,IF(Z$5<$T51,0,$D51*$X51*(1+$J51)^FLOOR((Z$5-$R51)/12,1)/12)))) -> 0 | AA51: =IF($D51="",0,IF(AA$5<$N51,0,IF(AA$5<=$O51,$D51*$H51*(1+$J51)^FLOOR((AA$5-1)/12,1)/12,IF(AA$5<$T51,0,$D51*$X51*(1+$J51)^FLOOR((AA$5-$R51)/12,1)/12)))) -> 0 | AB51: =IF($D51="",0,IF(AB$5<$N51,0,IF(AB$5<=$O51,$D51*$H51*(1+$J51)^FLOOR((AB$5-1)/12,1)/12,IF(AB$5<$T51,0,$D51*$X51*(1+$J51)^FLOOR((AB$5-$R51)/12,1)/12)))) -> 0 | AC51: =IF($D51="",0,IF(AC$5<$N51,0,IF(AC$5<=$O51,$D51*$H51*(1+$J51)^FLOOR((AC$5-1)/12,1)/12,IF(AC$5<$T51,0,$D51*$X51*(1+$J51)^FLOOR((AC$5-$R51)/12,1)/12)))) -> 0 | AD51: =IF($D51="",0,IF(AD$5<$N51,0,IF(AD$5<=$O51,$D51*$H51*(1+$J51)^FLOOR((AD$5-1)/12,1)/12,IF(AD$5<$T51,0,$D51*$X51*(1+$J51)^FLOOR((AD$5-$R51)/12,1)/12)))) -> 0 | AE51: =IF($D51="",0,IF(AE$5<$N51,0,IF(AE$5<=$O51,$D51*$H51*(1+$J51)^FLOOR((AE$5-1)/12,1)/12,IF(AE$5<$T51,0,$D51*$X51*(1+$J51)^FLOOR((AE$5-$R51)/12,1)/12)))) -> 0 | AF51: =IF($D51="",0,IF(AF$5<$N51,0,IF(AF$5<=$O51,$D51*$H51*(1+$J51)^FLOOR((AF$5-1)/12,1)/12,IF(AF$5<$T51,0,$D51*$X51*(1+$J51)^FLOOR((AF$5-$R51)/12,1)/12)))) -> 0 | ... EN51: =IF($D51="",0,IF(EN$5<$N51,0,IF(EN$5<=$O51,$D51*$H51*(1+$J51)^FLOOR((EN$5-1)/12,1)/12,IF(EN$5<$T51,0,$D51*$X51*(1+$J51)^FLOOR((EN$5-$R51)/12,1)/12)))) -> 0
E52: =IFERROR(D52/TotalSF,0) -> 0 | I52: =IFERROR(D52*H52,0) -> 0 | N52: =IF(F52="",0,(YEAR(F52)-YEAR(AnalysisStart))*12+(MONTH(F52)-MONTH(AnalysisStart))+1) -> 0 | O52: =IF(G52="",0,(YEAR(G52)-YEAR(AnalysisStart))*12+(MONTH(G52)-MONTH(AnalysisStart))+1) -> 0 | P52: =IF(D52="",0,MAX(1,O52+1)) -> 0 | Q52: =IF(D52="",0,Downtime_Ren*Retention_Ratio+Downtime_New*(1-Retention_Ratio)) -> 0 | R52: =IF(D52="",0,MIN(120,P52+Q52)) -> 0 | S52: =IF(D52="",0,FreeRent_New*(1-Retention_Ratio)+FreeRent_Ren*Retention_Ratio) -> 0 | T52: =IF(D52="",0,MIN(121,R52+S52)) -> 0 | U52: =IF(D52="",0,MIN(10,MAX(1,CEILING(R52/12,1)))) -> 0 | V52: =IF(D52="",0,(Retention_Ratio*TI_Ren+(1-Retention_Ratio)*TI_New)*D52) -> 0 | W52: =IF(D52="",0,Retention_Ratio*LC_Ren*LeaseTermYrs*'Rent Roll'!D52*'Rent Roll'!X52+(1-Retention_Ratio)*LC_Ren*LeaseTermYrs*'Rent Roll'!D52*'Rent Roll'!X52) -> 0 | X52: =IF(D52="",0,L52*INDEX(MktRentSchedule,U52)/MktRentY1) -> 0 | Y52: =IF($D52="",0,IF(Y$5<$N52,0,IF(Y$5<=$O52,$D52*$H52*(1+$J52)^FLOOR((Y$5-1)/12,1)/12,IF(Y$5<$T52,0,$D52*$X52*(1+$J52)^FLOOR((Y$5-$R52)/12,1)/12)))) -> 0 | Z52: =IF($D52="",0,IF(Z$5<$N52,0,IF(Z$5<=$O52,$D52*$H52*(1+$J52)^FLOOR((Z$5-1)/12,1)/12,IF(Z$5<$T52,0,$D52*$X52*(1+$J52)^FLOOR((Z$5-$R52)/12,1)/12)))) -> 0 | AA52: =IF($D52="",0,IF(AA$5<$N52,0,IF(AA$5<=$O52,$D52*$H52*(1+$J52)^FLOOR((AA$5-1)/12,1)/12,IF(AA$5<$T52,0,$D52*$X52*(1+$J52)^FLOOR((AA$5-$R52)/12,1)/12)))) -> 0 | AB52: =IF($D52="",0,IF(AB$5<$N52,0,IF(AB$5<=$O52,$D52*$H52*(1+$J52)^FLOOR((AB$5-1)/12,1)/12,IF(AB$5<$T52,0,$D52*$X52*(1+$J52)^FLOOR((AB$5-$R52)/12,1)/12)))) -> 0 | AC52: =IF($D52="",0,IF(AC$5<$N52,0,IF(AC$5<=$O52,$D52*$H52*(1+$J52)^FLOOR((AC$5-1)/12,1)/12,IF(AC$5<$T52,0,$D52*$X52*(1+$J52)^FLOOR((AC$5-$R52)/12,1)/12)))) -> 0 | AD52: =IF($D52="",0,IF(AD$5<$N52,0,IF(AD$5<=$O52,$D52*$H52*(1+$J52)^FLOOR((AD$5-1)/12,1)/12,IF(AD$5<$T52,0,$D52*$X52*(1+$J52)^FLOOR((AD$5-$R52)/12,1)/12)))) -> 0 | AE52: =IF($D52="",0,IF(AE$5<$N52,0,IF(AE$5<=$O52,$D52*$H52*(1+$J52)^FLOOR((AE$5-1)/12,1)/12,IF(AE$5<$T52,0,$D52*$X52*(1+$J52)^FLOOR((AE$5-$R52)/12,1)/12)))) -> 0 | AF52: =IF($D52="",0,IF(AF$5<$N52,0,IF(AF$5<=$O52,$D52*$H52*(1+$J52)^FLOOR((AF$5-1)/12,1)/12,IF(AF$5<$T52,0,$D52*$X52*(1+$J52)^FLOOR((AF$5-$R52)/12,1)/12)))) -> 0 | ... EN52: =IF($D52="",0,IF(EN$5<$N52,0,IF(EN$5<=$O52,$D52*$H52*(1+$J52)^FLOOR((EN$5-1)/12,1)/12,IF(EN$5<$T52,0,$D52*$X52*(1+$J52)^FLOOR((EN$5-$R52)/12,1)/12)))) -> 0
